Workbook
Name Alpha: 'Statistical Analysis'!$B$34
Name KurtScore: 'Statistical Analysis'!$B$31
Name MaxScore: 'Quiz 1 Grades'!$L$5
Name MeanScore: 'Statistical Analysis'!$B$16
Name MedianScore: 'Statistical Analysis'!$B$17
Name nGraded: 'Statistical Analysis'!$B$15
Name SDScore: 'Statistical Analysis'!$B$18
Name SkewScore: 'Statistical Analysis'!$B$30
Name Totals: 'Quiz 1 Grades'!$L$7:$L$58

Sheet Read Me
A1: Student Roster & Quiz 1 Grades
A2: Engineering Design · Fall 2026 · Teaching Assistant gradebook (rebuilt from 'Califications Quiz 1.xlsx' — the original file was not modified)
A4: Tabs in this workbook
A5: Roster | B5: Master list of the 52 students (last / first name). Type each student's Group # (column E). Quiz 1 score is pulled in automatically.
A6: Groups | B6: One row per project group (up to 13): choose the project track, see group size, size check and group Quiz 1 average; class split totals below.
A7: Quiz 1 Grades | B7: Score per sub-question. Problem subtotals, total (/50), %, performance band, rank and status are formulas. Class averages at the bottom.
A8: Performance per Problem | B8: Statistics for every sub-question (average, % of max, median, std dev, full marks, zeros) + charts. The Flag column tells you what to review in class.
A9: Class Summary | B9: Class-level numbers: graded / missing, average, median, high / low, performance bands and score distribution chart.
A10: Statistical Analysis | B10: Gaussian (normal) analysis: descriptive statistics with a confidence interval, five normality tests (Shapiro–Wilk, Anderson–Darling, Jarque–Bera, skewness & kurtosis z), empirical ±σ rule, histogram vs. normal curve, Q–Q plot, question analysis (difficulty, discrimination, Cronbach's α) and each student's z-score. Key findings at the top are written by formulas.
A12: Color legend
A13: Blue text, pale-yellow cell | B13: A value you type (scores, max points, group #, tracks, thresholds).
A14: Black text | B14: A formula — do not type over it; it updates automatically.
A15: Yellow row (Quiz 1 Grades) | B15: Student has no Quiz 1 scores yet (status = Missing).
A16: Green / yellow / red total | B16: Performance band: Strong / Satisfactory / Needs support (thresholds editable on Quiz 1 Grades, cells S3:S4).
A17: Red number | B17: A score of 0 on that sub-question.
A19: How to…
A20: Enter a missing score | B20: Go to Quiz 1 Grades and type the points in the blue cells of that student's row. Everything else recalculates.
A21: Partly graded quiz | B21: If some sub-scores are still blank, the Status shows 'Incomplete' and the student is left out of the total, rank and class statistics until every sub-score is entered.
A22: Add a student | B22: Insert a new row INSIDE the tables (above the last student) on both Roster and Quiz 1 Grades, then copy the formulas down from the row above. All totals and statistics expand automatically.
A23: Form project groups | B23: Roster → pick a Group # for each student (column E, drop-down). Groups tab → choose the project track for each group. Sizes, tracks and averages update automatically.
A24: Change max points | B24: Quiz 1 Grades row 5 (blue cells, 'Max points'). Subtotals, %, statistics and score limits follow.
A25: Sort / filter | B25: Use the filter arrows on Quiz 1 Grades row 6 (e.g., sort by TOTAL, filter Performance = 'Needs support'). The max-points row and thresholds stay put; names follow the # automatically.
A27: Notes & assumptions
A28: Max points | B28: 1.1 = 10, 1.2 = 15, 1.3 A = 5, 1.3 B = 5 (Problem 1 = 35) and 2.1 = 2.2 = 2.3 = 5 (Problem 2 = 15), total 50. Problem totals come from the original headers; the split per sub-question was inferred from the highest scores recorded and the original per-problem color bands — confirm with the instructor.
A29: Missing quizzes | B29: Gavin Cappel and Michelle Gutierrez have no Quiz 1 scores (they were highlighted yellow in the original file). They are excluded from averages until scores are entered.
A30: Performance bands | B30: Kept from the original file's color rules: 40–50 green, 26–39 yellow, 0–25 red.
A31: Names | B31: Trailing spaces were removed and names split into Last / First (last word = last name). Please double-check spellings against Canvas (e.g., 'Jermy Brown').

Sheet Roster
A1: Class Roster
A2: Pick a Group # for each student (blue drop-down). Set each group's project track on the Groups tab → the student's track fills in automatically.
A4: # | B4: Last Name | C4: First Name | D4: Full Name | E4: Group # | F4: Project Track | G4: Quiz 1 (/50) | H4: Quiz 1 % | I4: Group key (helper — do not edit)
A5: 1 | B5: Abagwe | C5: David | D5: =TRIM(C5&" "&B5) -> David Abagwe | E5: 5A | F5: =IF(E5="","Unassigned",IFERROR(IF(INDEX(Groups!$B$5:$B$17,MATCH(E5,Groups!$A$5:$A$17,0))="","Track not set",INDEX(Groups!$B$5:$B$17,MATCH(E5,Groups!$A$5:$A$17,0))),"Group not in table")) -> Methylene Blue Removal | G5: =IFERROR(IF(INDEX('Quiz 1 Grades'!$P$7:$P$58,MATCH($A5,'Quiz 1 Grades'!$A$7:$A$58,0))="Graded",INDEX('Quiz 1 Grades'!$L$7:$L$58,MATCH($A5,'Quiz 1 Grades'!$A$7:$A$58,0)),INDEX('Quiz 1 Grades'!$P$7:$P$58,MATCH($A5,'Quiz 1 Grades'!$A$7:$A$58,0))),"") -> 44 | H5: =IF(ISNUMBER(G5),G5/'Quiz 1 Grades'!$L$5,"") -> 0.88 | I5: =IF(E5="","",E5&"#"&SUMPRODUCT(($E$5:E5=E5)*1)) -> 5A#1
A6: 2 | B6: Acharya | C6: Sonu | D6: =TRIM(C6&" "&B6) -> Sonu Acharya | E6: 1A | F6: =IF(E6="","Unassigned",IFERROR(IF(INDEX(Groups!$B$5:$B$17,MATCH(E6,Groups!$A$5:$A$17,0))="","Track not set",INDEX(Groups!$B$5:$B$17,MATCH(E6,Groups!$A$5:$A$17,0))),"Group not in table")) -> Methylene Blue Removal | G6: =IFERROR(IF(INDEX('Quiz 1 Grades'!$P$7:$P$58,MATCH($A6,'Quiz 1 Grades'!$A$7:$A$58,0))="Graded",INDEX('Quiz 1 Grades'!$L$7:$L$58,MATCH($A6,'Quiz 1 Grades'!$A$7:$A$58,0)),INDEX('Quiz 1 Grades'!$P$7:$P$58,MATCH($A6,'Quiz 1 Grades'!$A$7:$A$58,0))),"") -> 21 | H6: =IF(ISNUMBER(G6),G6/'Quiz 1 Grades'!$L$5,"") -> 0.42 | I6: =IF(E6="","",E6&"#"&SUMPRODUCT(($E$5:E6=E6)*1)) -> 1A#1
A7: 3 | B7: Adams | C7: Ashton | D7: =TRIM(C7&" "&B7) -> Ashton Adams | E7: 4B | F7: =IF(E7="","Unassigned",IFERROR(IF(INDEX(Groups!$B$5:$B$17,MATCH(E7,Groups!$A$5:$A$17,0))="","Track not set",INDEX(Groups!$B$5:$B$17,MATCH(E7,Groups!$A$5:$A$17,0))),"Group not in table")) -> Oxygenation | G7: =IFERROR(IF(INDEX('Quiz 1 Grades'!$P$7:$P$58,MATCH($A7,'Quiz 1 Grades'!$A$7:$A$58,0))="Graded",INDEX('Quiz 1 Grades'!$L$7:$L$58,MATCH($A7,'Quiz 1 Grades'!$A$7:$A$58,0)),INDEX('Quiz 1 Grades'!$P$7:$P$58,MATCH($A7,'Quiz 1 Grades'!$A$7:$A$58,0))),"") -> 43 | H7: =IF(ISNUMBER(G7),G7/'Quiz 1 Grades'!$L$5,"") -> 0.86 | I7: =IF(E7="","",E7&"#"&SUMPRODUCT(($E$5:E7=E7)*1)) -> 4B#1
A8: 4 | B8: Albert | C8: Hayden | D8: =TRIM(C8&" "&B8) -> Hayden Albert | E8: 1A | F8: =IF(E8="","Unassigned",IFERROR(IF(INDEX(Groups!$B$5:$B$17,MATCH(E8,Groups!$A$5:$A$17,0))="","Track not set",INDEX(Groups!$B$5:$B$17,MATCH(E8,Groups!$A$5:$A$17,0))),"Group not in table")) -> Methylene Blue Removal | G8: =IFERROR(IF(INDEX('Quiz 1 Grades'!$P$7:$P$58,MATCH($A8,'Quiz 1 Grades'!$A$7:$A$58,0))="Graded",INDEX('Quiz 1 Grades'!$L$7:$L$58,MATCH($A8,'Quiz 1 Grades'!$A$7:$A$58,0)),INDEX('Quiz 1 Grades'!$P$7:$P$58,MATCH($A8,'Quiz 1 Grades'!$A$7:$A$58,0))),"") -> 43 | H8: =IF(ISNUMBER(G8),G8/'Quiz 1 Grades'!$L$5,"") -> 0.86 | I8: =IF(E8="","",E8&"#"&SUMPRODUCT(($E$5:E8=E8)*1)) -> 1A#2
A9: 5 | B9: Allen | C9: Lani | D9: =TRIM(C9&" "&B9) -> Lani Allen | E9: 3B | F9: =IF(E9="","Unassigned",IFERROR(IF(INDEX(Groups!$B$5:$B$17,MATCH(E9,Groups!$A$5:$A$17,0))="","Track not set",INDEX(Groups!$B$5:$B$17,MATCH(E9,Groups!$A$5:$A$17,0))),"Group not in table")) -> Oxygenation | G9: =IFERROR(IF(INDEX('Quiz 1 Grades'!$P$7:$P$58,MATCH($A9,'Quiz 1 Grades'!$A$7:$A$58,0))="Graded",INDEX('Quiz 1 Grades'!$L$7:$L$58,MATCH($A9,'Quiz 1 Grades'!$A$7:$A$58,0)),INDEX('Quiz 1 Grades'!$P$7:$P$58,MATCH($A9,'Quiz 1 Grades'!$A$7:$A$58,0))),"") -> 50 | H9: =IF(ISNUMBER(G9),G9/'Quiz 1 Grades'!$L$5,"") -> 1 | I9: =IF(E9="","",E9&"#"&SUMPRODUCT(($E$5:E9=E9)*1)) -> 3B#1
A10: 6 | B10: Andrade | C10: John David | D10: =TRIM(C10&" "&B10) -> John David Andrade | E10: 4A | F10: =IF(E10="","Unassigned",IFERROR(IF(INDEX(Groups!$B$5:$B$17,MATCH(E10,Groups!$A$5:$A$17,0))="","Track not set",INDEX(Groups!$B$5:$B$17,MATCH(E10,Groups!$A$5:$A$17,0))),"Group not in table")) -> Methylene Blue Removal | G10: =IFERROR(IF(INDEX('Quiz 1 Grades'!$P$7:$P$58,MATCH($A10,'Quiz 1 Grades'!$A$7:$A$58,0))="Graded",INDEX('Quiz 1 Grades'!$L$7:$L$58,MATCH($A10,'Quiz 1 Grades'!$A$7:$A$58,0)),INDEX('Quiz 1 Grades'!$P$7:$P$58,MATCH($A10,'Quiz 1 Grades'!$A$7:$A$58,0))),"") -> 32 | H10: =IF(ISNUMBER(G10),G10/'Quiz 1 Grades'!$L$5,"") -> 0.64 | I10: =IF(E10="","",E10&"#"&SUMPRODUCT(($E$5:E10=E10)*1)) -> 4A#1
A11: 7 | B11: Atkins | C11: Landon | D11: =TRIM(C11&" "&B11) -> Landon Atkins | E11: 3A | F11: =IF(E11="","Unassigned",IFERROR(IF(INDEX(Groups!$B$5:$B$17,MATCH(E11,Groups!$A$5:$A$17,0))="","Track not set",INDEX(Groups!$B$5:$B$17,MATCH(E11,Groups!$A$5:$A$17,0))),"Group not in table")) -> Methylene Blue Removal | G11: =IFERROR(IF(INDEX('Quiz 1 Grades'!$P$7:$P$58,MATCH($A11,'Quiz 1 Grades'!$A$7:$A$58,0))="Graded",INDEX('Quiz 1 Grades'!$L$7:$L$58,MATCH($A11,'Quiz 1 Grades'!$A$7:$A$58,0)),INDEX('Quiz 1 Grades'!$P$7:$P$58,MATCH($A11,'Quiz 1 Grades'!$A$7:$A$58,0))),"") -> 26 | H11: =IF(ISNUMBER(G11),G11/'Quiz 1 Grades'!$L$5,"") -> 0.52 | I11: =IF(E11="","",E11&"#"&SUMPRODUCT(($E$5:E11=E11)*1)) -> 3A#1
A12: 8 | B12: Borkland | C12: Ryan | D12: =TRIM(C12&" "&B12) -> Ryan Borkland | E12: 1B | F12: =IF(E12="","Unassigned",IFERROR(IF(INDEX(Groups!$B$5:$B$17,MATCH(E12,Groups!$A$5:$A$17,0))="","Track not set",INDEX(Groups!$B$5:$B$17,MATCH(E12,Groups!$A$5:$A$17,0))),"Group not in table")) -> Oxygenation | G12: =IFERROR(IF(INDEX('Quiz 1 Grades'!$P$7:$P$58,MATCH($A12,'Quiz 1 Grades'!$A$7:$A$58,0))="Graded",INDEX('Quiz 1 Grades'!$L$7:$L$58,MATCH($A12,'Quiz 1 Grades'!$A$7:$A$58,0)),INDEX('Quiz 1 Grades'!$P$7:$P$58,MATCH($A12,'Quiz 1 Grades'!$A$7:$A$58,0))),"") -> 46 | H12: =IF(ISNUMBER(G12),G12/'Quiz 1 Grades'!$L$5,"") -> 0.92 | I12: =IF(E12="","",E12&"#"&SUMPRODUCT(($E$5:E12=E12)*1)) -> 1B#1
A13: 9 | B13: Brown | C13: Jermy | D13: =TRIM(C13&" "&B13) -> Jermy Brown | E13: 4A | F13: =IF(E13="","Unassigned",IFERROR(IF(INDEX(Groups!$B$5:$B$17,MATCH(E13,Groups!$A$5:$A$17,0))="","Track not set",INDEX(Groups!$B$5:$B$17,MATCH(E13,Groups!$A$5:$A$17,0))),"Group not in table")) -> Methylene Blue Removal | G13: =IFERROR(IF(INDEX('Quiz 1 Grades'!$P$7:$P$58,MATCH($A13,'Quiz 1 Grades'!$A$7:$A$58,0))="Graded",INDEX('Quiz 1 Grades'!$L$7:$L$58,MATCH($A13,'Quiz 1 Grades'!$A$7:$A$58,0)),INDEX('Quiz 1 Grades'!$P$7:$P$58,MATCH($A13,'Quiz 1 Grades'!$A$7:$A$58,0))),"") -> 44 | H13: =IF(ISNUMBER(G13),G13/'Quiz 1 Grades'!$L$5,"") -> 0.88 | I13: =IF(E13="","",E13&"#"&SUMPRODUCT(($E$5:E13=E13)*1)) -> 4A#2
A14: 10 | B14: Calderon | C14: Eric | D14: =TRIM(C14&" "&B14) -> Eric Calderon | E14: 1B | F14: =IF(E14="","Unassigned",IFERROR(IF(INDEX(Groups!$B$5:$B$17,MATCH(E14,Groups!$A$5:$A$17,0))="","Track not set",INDEX(Groups!$B$5:$B$17,MATCH(E14,Groups!$A$5:$A$17,0))),"Group not in table")) -> Oxygenation | G14: =IFERROR(IF(INDEX('Quiz 1 Grades'!$P$7:$P$58,MATCH($A14,'Quiz 1 Grades'!$A$7:$A$58,0))="Graded",INDEX('Quiz 1 Grades'!$L$7:$L$58,MATCH($A14,'Quiz 1 Grades'!$A$7:$A$58,0)),INDEX('Quiz 1 Grades'!$P$7:$P$58,MATCH($A14,'Quiz 1 Grades'!$A$7:$A$58,0))),"") -> 38 | H14: =IF(ISNUMBER(G14),G14/'Quiz 1 Grades'!$L$5,"") -> 0.76 | I14: =IF(E14="","",E14&"#"&SUMPRODUCT(($E$5:E14=E14)*1)) -> 1B#2
A15: 11 | B15: Camarillo | C15: Angel | D15: =TRIM(C15&" "&B15) -> Angel Camarillo | E15: 5A | F15: =IF(E15="","Unassigned",IFERROR(IF(INDEX(Groups!$B$5:$B$17,MATCH(E15,Groups!$A$5:$A$17,0))="","Track not set",INDEX(Groups!$B$5:$B$17,MATCH(E15,Groups!$A$5:$A$17,0))),"Group not in table")) -> Methylene Blue Removal | G15: =IFERROR(IF(INDEX('Quiz 1 Grades'!$P$7:$P$58,MATCH($A15,'Quiz 1 Grades'!$A$7:$A$58,0))="Graded",INDEX('Quiz 1 Grades'!$L$7:$L$58,MATCH($A15,'Quiz 1 Grades'!$A$7:$A$58,0)),INDEX('Quiz 1 Grades'!$P$7:$P$58,MATCH($A15,'Quiz 1 Grades'!$A$7:$A$58,0))),"") -> 26 | H15: =IF(ISNUMBER(G15),G15/'Quiz 1 Grades'!$L$5,"") -> 0.52 | I15: =IF(E15="","",E15&"#"&SUMPRODUCT(($E$5:E15=E15)*1)) -> 5A#2
A16: 12 | B16: Cappel | C16: Gavin | D16: =TRIM(C16&" "&B16) -> Gavin Cappel | E16: 1B | F16: =IF(E16="","Unassigned",IFERROR(IF(INDEX(Groups!$B$5:$B$17,MATCH(E16,Groups!$A$5:$A$17,0))="","Track not set",INDEX(Groups!$B$5:$B$17,MATCH(E16,Groups!$A$5:$A$17,0))),"Group not in table")) -> Oxygenation | G16: =IFERROR(IF(INDEX('Quiz 1 Grades'!$P$7:$P$58,MATCH($A16,'Quiz 1 Grades'!$A$7:$A$58,0))="Graded",INDEX('Quiz 1 Grades'!$L$7:$L$58,MATCH($A16,'Quiz 1 Grades'!$A$7:$A$58,0)),INDEX('Quiz 1 Grades'!$P$7:$P$58,MATCH($A16,'Quiz 1 Grades'!$A$7:$A$58,0))),"") -> Missing | H16: =IF(ISNUMBER(G16),G16/'Quiz 1 Grades'!$L$5,"") | I16: =IF(E16="","",E16&"#"&SUMPRODUCT(($E$5:E16=E16)*1)) -> 1B#3
... A56: 52 | B56: Wildman | C56: Shaman | D56: =TRIM(C56&" "&B56) -> Shaman Wildman | E56: 2A | F56: =IF(E56="","Unassigned",IFERROR(IF(INDEX(Groups!$B$5:$B$17,MATCH(E56,Groups!$A$5:$A$17,0))="","Track not set",INDEX(Groups!$B$5:$B$17,MATCH(E56,Groups!$A$5:$A$17,0))),"Group not in table")) -> Methylene Blue Removal | G56: =IFERROR(IF(INDEX('Quiz 1 Grades'!$P$7:$P$58,MATCH($A56,'Quiz 1 Grades'!$A$7:$A$58,0))="Graded",INDEX('Quiz 1 Grades'!$L$7:$L$58,MATCH($A56,'Quiz 1 Grades'!$A$7:$A$58,0)),INDEX('Quiz 1 Grades'!$P$7:$P$58,MATCH($A56,'Quiz 1 Grades'!$A$7:$A$58,0))),"") -> 41 | H56: =IF(ISNUMBER(G56),G56/'Quiz 1 Grades'!$L$5,"") -> 0.82 | I56: =IF(E56="","",E56&"#"&SUMPRODUCT(($E$5:E56=E56)*1)) -> 2A#4

Sheet Groups
A1: Project Groups
A2: Choose each group's project track (blue). Students are assigned on the Roster tab (column E). Group size, size check and averages are formulas.
A4: Group # | B4: Project Track (choose) | C4: # Students | D4: Size check | E4: Avg Quiz 1 %
A5: 1A | B5: Methylene Blue Removal | C5: =COUNTIF(Roster!$I$5:$I$56,A5&"#*") -> 5 | D5: =IF(C5=0,"",IF(OR(C5<$C$26,C5>$C$27),"Check size","OK")) | E5: =IFERROR(AVERAGEIF(Roster!$I$5:$I$56,A5&"#*",Roster!$H$5:$H$56),"") -> 0.648
A6: 2A | B6: Methylene Blue Removal | C6: =COUNTIF(Roster!$I$5:$I$56,A6&"#*") -> 4 | D6: =IF(C6=0,"",IF(OR(C6<$C$26,C6>$C$27),"Check size","OK")) | E6: =IFERROR(AVERAGEIF(Roster!$I$5:$I$56,A6&"#*",Roster!$H$5:$H$56),"") -> 0.665
A7: 3A | B7: Methylene Blue Removal | C7: =COUNTIF(Roster!$I$5:$I$56,A7&"#*") -> 5 | D7: =IF(C7=0,"",IF(OR(C7<$C$26,C7>$C$27),"Check size","OK")) | E7: =IFERROR(AVERAGEIF(Roster!$I$5:$I$56,A7&"#*",Roster!$H$5:$H$56),"") -> 0.672
A8: 4A | B8: Methylene Blue Removal | C8: =COUNTIF(Roster!$I$5:$I$56,A8&"#*") -> 5 | D8: =IF(C8=0,"",IF(OR(C8<$C$26,C8>$C$27),"Check size","OK")) | E8: =IFERROR(AVERAGEIF(Roster!$I$5:$I$56,A8&"#*",Roster!$H$5:$H$56),"") -> 0.74
A9: 5A | B9: Methylene Blue Removal | C9: =COUNTIF(Roster!$I$5:$I$56,A9&"#*") -> 5 | D9: =IF(C9=0,"",IF(OR(C9<$C$26,C9>$C$27),"Check size","OK")) | E9: =IFERROR(AVERAGEIF(Roster!$I$5:$I$56,A9&"#*",Roster!$H$5:$H$56),"") -> 0.668
A10: 1B | B10: Oxygenation | C10: =COUNTIF(Roster!$I$5:$I$56,A10&"#*") -> 5 | D10: =IF(C10=0,"",IF(OR(C10<$C$26,C10>$C$27),"Check size","OK")) | E10: =IFERROR(AVERAGEIF(Roster!$I$5:$I$56,A10&"#*",Roster!$H$5:$H$56),"") -> 0.89
A11: 2B | B11: Oxygenation | C11: =COUNTIF(Roster!$I$5:$I$56,A11&"#*") -> 5 | D11: =IF(C11=0,"",IF(OR(C11<$C$26,C11>$C$27),"Check size","OK")) | E11: =IFERROR(AVERAGEIF(Roster!$I$5:$I$56,A11&"#*",Roster!$H$5:$H$56),"") -> 0.888
A12: 3B | B12: Oxygenation | C12: =COUNTIF(Roster!$I$5:$I$56,A12&"#*") -> 5 | D12: =IF(C12=0,"",IF(OR(C12<$C$26,C12>$C$27),"Check size","OK")) | E12: =IFERROR(AVERAGEIF(Roster!$I$5:$I$56,A12&"#*",Roster!$H$5:$H$56),"") -> 0.832
A13: 4B | B13: Oxygenation | C13: =COUNTIF(Roster!$I$5:$I$56,A13&"#*") -> 5 | D13: =IF(C13=0,"",IF(OR(C13<$C$26,C13>$C$27),"Check size","OK")) | E13: =IFERROR(AVERAGEIF(Roster!$I$5:$I$56,A13&"#*",Roster!$H$5:$H$56),"") -> 0.805
A14: 5B | B14: Oxygenation | C14: =COUNTIF(Roster!$I$5:$I$56,A14&"#*") -> 4 | D14: =IF(C14=0,"",IF(OR(C14<$C$26,C14>$C$27),"Check size","OK")) | E14: =IFERROR(AVERAGEIF(Roster!$I$5:$I$56,A14&"#*",Roster!$H$5:$H$56),"") -> 0.875
A15: 6B | B15: Oxygenation | C15: =COUNTIF(Roster!$I$5:$I$56,A15&"#*") -> 4 | D15: =IF(C15=0,"",IF(OR(C15<$C$26,C15>$C$27),"Check size","OK")) | E15: =IFERROR(AVERAGEIF(Roster!$I$5:$I$56,A15&"#*",Roster!$H$5:$H$56),"") -> 0.745
C16: =COUNTIF(Roster!$I$5:$I$56,A16&"#*") -> 0 | D16: =IF(C16=0,"",IF(OR(C16<$C$26,C16>$C$27),"Check size","OK")) | E16: =IFERROR(AVERAGEIF(Roster!$I$5:$I$56,A16&"#*",Roster!$H$5:$H$56),"")
C17: =COUNTIF(Roster!$I$5:$I$56,A17&"#*") -> 0 | D17: =IF(C17=0,"",IF(OR(C17<$C$26,C17>$C$27),"Check size","OK")) | E17: =IFERROR(AVERAGEIF(Roster!$I$5:$I$56,A17&"#*",Roster!$H$5:$H$56),"")
A19: Class split & group sizing
A20: Students on roster | C20: =COUNTA(Roster!$B$5:$B$56) -> 52
A21: Assigned to a group | C21: =COUNTA(Roster!$E$5:$E$56) -> 52
A22: Not yet assigned | C22: =COUNTBLANK(Roster!$E$5:$E$56) -> 0
A23: Methylene Blue Removal students | C23: =COUNTIF(Roster!$F$5:$F$56,"Methylene Blue Removal") -> 24
A24: Oxygenation students | C24: =COUNTIF(Roster!$F$5:$F$56,"Oxygenation") -> 28
A25: Groups on Methylene Blue Removal | C25: =COUNTIFS($B$5:$B$17,"Methylene Blue Removal",$C$5:$C$17,">0") -> 5
A26: Minimum students per group | C26: 4
A27: Maximum students per group | C27: 5
A28: Groups needed (at max size) | C28: =ROUNDUP(C20/C27,0) -> 11

Sheet Group Members & Budget
A1: Group Members & Budget
A2: Who is in each group and how much each group can spend. Everything here reads from the Roster (column E) and Groups tabs. Budget = $ per student × students, capped per group (blue cells).
A4: Budget rule
A5: Budget per student | C5: 20
A6: Maximum per group | C6: 80
A8: Group | B8: Project track | C8: # Students | D8: Budget ($) | E8: Member 1 | F8: Member 2 | G8: Member 3 | H8: Member 4 | I8: Member 5 | J8: Member 6
A9: =IF(Groups!A5="","",Groups!A5) -> 1A | B9: =IF(A9="","",IF(Groups!B5="","Track not set",Groups!B5)) -> Methylene Blue Removal | C9: =IF(A9="","",Groups!C5) -> 5 | D9: =IF(A9="","",MIN(C9*$C$5,$C$6)) -> 80 | E9: =IF($A9="","",IFERROR(INDEX(Roster!$D$5:$D$56,MATCH($A9&"#"&1,Roster!$I$5:$I$56,0)),"")) -> Sonu Acharya | F9: =IF($A9="","",IFERROR(INDEX(Roster!$D$5:$D$56,MATCH($A9&"#"&2,Roster!$I$5:$I$56,0)),"")) -> Hayden Albert | G9: =IF($A9="","",IFERROR(INDEX(Roster!$D$5:$D$56,MATCH($A9&"#"&3,Roster!$I$5:$I$56,0)),"")) -> Elizabeth Dillah | H9: =IF($A9="","",IFERROR(INDEX(Roster!$D$5:$D$56,MATCH($A9&"#"&4,Roster!$I$5:$I$56,0)),"")) -> Hunter Gates | I9: =IF($A9="","",IFERROR(INDEX(Roster!$D$5:$D$56,MATCH($A9&"#"&5,Roster!$I$5:$I$56,0)),"")) -> Macie Perrio | J9: =IF($A9="","",IFERROR(INDEX(Roster!$D$5:$D$56,MATCH($A9&"#"&6,Roster!$I$5:$I$56,0)),""))
A10: =IF(Groups!A6="","",Groups!A6) -> 2A | B10: =IF(A10="","",IF(Groups!B6="","Track not set",Groups!B6)) -> Methylene Blue Removal | C10: =IF(A10="","",Groups!C6) -> 4 | D10: =IF(A10="","",MIN(C10*$C$5,$C$6)) -> 80 | E10: =IF($A10="","",IFERROR(INDEX(Roster!$D$5:$D$56,MATCH($A10&"#"&1,Roster!$I$5:$I$56,0)),"")) -> Trevin Cutrer | F10: =IF($A10="","",IFERROR(INDEX(Roster!$D$5:$D$56,MATCH($A10&"#"&2,Roster!$I$5:$I$56,0)),"")) -> Rachel Holmes | G10: =IF($A10="","",IFERROR(INDEX(Roster!$D$5:$D$56,MATCH($A10&"#"&3,Roster!$I$5:$I$56,0)),"")) -> Noah Rodriguez | H10: =IF($A10="","",IFERROR(INDEX(Roster!$D$5:$D$56,MATCH($A10&"#"&4,Roster!$I$5:$I$56,0)),"")) -> Shaman Wildman | I10: =IF($A10="","",IFERROR(INDEX(Roster!$D$5:$D$56,MATCH($A10&"#"&5,Roster!$I$5:$I$56,0)),"")) | J10: =IF($A10="","",IFERROR(INDEX(Roster!$D$5:$D$56,MATCH($A10&"#"&6,Roster!$I$5:$I$56,0)),""))
A11: =IF(Groups!A7="","",Groups!A7) -> 3A | B11: =IF(A11="","",IF(Groups!B7="","Track not set",Groups!B7)) -> Methylene Blue Removal | C11: =IF(A11="","",Groups!C7) -> 5 | D11: =IF(A11="","",MIN(C11*$C$5,$C$6)) -> 80 | E11: =IF($A11="","",IFERROR(INDEX(Roster!$D$5:$D$56,MATCH($A11&"#"&1,Roster!$I$5:$I$56,0)),"")) -> Landon Atkins | F11: =IF($A11="","",IFERROR(INDEX(Roster!$D$5:$D$56,MATCH($A11&"#"&2,Roster!$I$5:$I$56,0)),"")) -> Axel Cruz-Hernandez | G11: =IF($A11="","",IFERROR(INDEX(Roster!$D$5:$D$56,MATCH($A11&"#"&3,Roster!$I$5:$I$56,0)),"")) -> Mia Cuellar | H11: =IF($A11="","",IFERROR(INDEX(Roster!$D$5:$D$56,MATCH($A11&"#"&4,Roster!$I$5:$I$56,0)),"")) -> Connor Felux | I11: =IF($A11="","",IFERROR(INDEX(Roster!$D$5:$D$56,MATCH($A11&"#"&5,Roster!$I$5:$I$56,0)),"")) -> Kara Larsen | J11: =IF($A11="","",IFERROR(INDEX(Roster!$D$5:$D$56,MATCH($A11&"#"&6,Roster!$I$5:$I$56,0)),""))
A12: =IF(Groups!A8="","",Groups!A8) -> 4A | B12: =IF(A12="","",IF(Groups!B8="","Track not set",Groups!B8)) -> Methylene Blue Removal | C12: =IF(A12="","",Groups!C8) -> 5 | D12: =IF(A12="","",MIN(C12*$C$5,$C$6)) -> 80 | E12: =IF($A12="","",IFERROR(INDEX(Roster!$D$5:$D$56,MATCH($A12&"#"&1,Roster!$I$5:$I$56,0)),"")) -> John David Andrade | F12: =IF($A12="","",IFERROR(INDEX(Roster!$D$5:$D$56,MATCH($A12&"#"&2,Roster!$I$5:$I$56,0)),"")) -> Jermy Brown | G12: =IF($A12="","",IFERROR(INDEX(Roster!$D$5:$D$56,MATCH($A12&"#"&3,Roster!$I$5:$I$56,0)),"")) -> Devin Cuellar | H12: =IF($A12="","",IFERROR(INDEX(Roster!$D$5:$D$56,MATCH($A12&"#"&4,Roster!$I$5:$I$56,0)),"")) -> Brinda Gayen | I12: =IF($A12="","",IFERROR(INDEX(Roster!$D$5:$D$56,MATCH($A12&"#"&5,Roster!$I$5:$I$56,0)),"")) -> Emmalie Potter | J12: =IF($A12="","",IFERROR(INDEX(Roster!$D$5:$D$56,MATCH($A12&"#"&6,Roster!$I$5:$I$56,0)),""))
A13: =IF(Groups!A9="","",Groups!A9) -> 5A | B13: =IF(A13="","",IF(Groups!B9="","Track not set",Groups!B9)) -> Methylene Blue Removal | C13: =IF(A13="","",Groups!C9) -> 5 | D13: =IF(A13="","",MIN(C13*$C$5,$C$6)) -> 80 | E13: =IF($A13="","",IFERROR(INDEX(Roster!$D$5:$D$56,MATCH($A13&"#"&1,Roster!$I$5:$I$56,0)),"")) -> David Abagwe | F13: =IF($A13="","",IFERROR(INDEX(Roster!$D$5:$D$56,MATCH($A13&"#"&2,Roster!$I$5:$I$56,0)),"")) -> Angel Camarillo | G13: =IF($A13="","",IFERROR(INDEX(Roster!$D$5:$D$56,MATCH($A13&"#"&3,Roster!$I$5:$I$56,0)),"")) -> Mihal Jacob | H13: =IF($A13="","",IFERROR(INDEX(Roster!$D$5:$D$56,MATCH($A13&"#"&4,Roster!$I$5:$I$56,0)),"")) -> Diego Leal | I13: =IF($A13="","",IFERROR(INDEX(Roster!$D$5:$D$56,MATCH($A13&"#"&5,Roster!$I$5:$I$56,0)),"")) -> Aaron Linhart | J13: =IF($A13="","",IFERROR(INDEX(Roster!$D$5:$D$56,MATCH($A13&"#"&6,Roster!$I$5:$I$56,0)),""))
A14: =IF(Groups!A10="","",Groups!A10) -> 1B | B14: =IF(A14="","",IF(Groups!B10="","Track not set",Groups!B10)) -> Oxygenation | C14: =IF(A14="","",Groups!C10) -> 5 | D14: =IF(A14="","",MIN(C14*$C$5,$C$6)) -> 80 | E14: =IF($A14="","",IFERROR(INDEX(Roster!$D$5:$D$56,MATCH($A14&"#"&1,Roster!$I$5:$I$56,0)),"")) -> Ryan Borkland | F14: =IF($A14="","",IFERROR(INDEX(Roster!$D$5:$D$56,MATCH($A14&"#"&2,Roster!$I$5:$I$56,0)),"")) -> Eric Calderon | G14: =IF($A14="","",IFERROR(INDEX(Roster!$D$5:$D$56,MATCH($A14&"#"&3,Roster!$I$5:$I$56,0)),"")) -> Gavin Cappel | H14: =IF($A14="","",IFERROR(INDEX(Roster!$D$5:$D$56,MATCH($A14&"#"&4,Roster!$I$5:$I$56,0)),"")) -> Isabella Juarez | I14: =IF($A14="","",IFERROR(INDEX(Roster!$D$5:$D$56,MATCH($A14&"#"&5,Roster!$I$5:$I$56,0)),"")) -> Kayra Rushing | J14: =IF($A14="","",IFERROR(INDEX(Roster!$D$5:$D$56,MATCH($A14&"#"&6,Roster!$I$5:$I$56,0)),""))
A15: =IF(Groups!A11="","",Groups!A11) -> 2B | B15: =IF(A15="","",IF(Groups!B11="","Track not set",Groups!B11)) -> Oxygenation | C15: =IF(A15="","",Groups!C11) -> 5 | D15: =IF(A15="","",MIN(C15*$C$5,$C$6)) -> 80 | E15: =IF($A15="","",IFERROR(INDEX(Roster!$D$5:$D$56,MATCH($A15&"#"&1,Roster!$I$5:$I$56,0)),"")) -> Venditha Chelikani | F15: =IF($A15="","",IFERROR(INDEX(Roster!$D$5:$D$56,MATCH($A15&"#"&2,Roster!$I$5:$I$56,0)),"")) -> Victoria Gaytan | G15: =IF($A15="","",IFERROR(INDEX(Roster!$D$5:$D$56,MATCH($A15&"#"&3,Roster!$I$5:$I$56,0)),"")) -> Emily Ickert | H15: =IF($A15="","",IFERROR(INDEX(Roster!$D$5:$D$56,MATCH($A15&"#"&4,Roster!$I$5:$I$56,0)),"")) -> Luke Presa | I15: =IF($A15="","",IFERROR(INDEX(Roster!$D$5:$D$56,MATCH($A15&"#"&5,Roster!$I$5:$I$56,0)),"")) -> Benny Reyes | J15: =IF($A15="","",IFERROR(INDEX(Roster!$D$5:$D$56,MATCH($A15&"#"&6,Roster!$I$5:$I$56,0)),""))
A16: =IF(Groups!A12="","",Groups!A12) -> 3B | B16: =IF(A16="","",IF(Groups!B12="","Track not set",Groups!B12)) -> Oxygenation | C16: =IF(A16="","",Groups!C12) -> 5 | D16: =IF(A16="","",MIN(C16*$C$5,$C$6)) -> 80 | E16: =IF($A16="","",IFERROR(INDEX(Roster!$D$5:$D$56,MATCH($A16&"#"&1,Roster!$I$5:$I$56,0)),"")) -> Lani Allen | F16: =IF($A16="","",IFERROR(INDEX(Roster!$D$5:$D$56,MATCH($A16&"#"&2,Roster!$I$5:$I$56,0)),"")) -> Jack Elsas | G16: =IF($A16="","",IFERROR(INDEX(Roster!$D$5:$D$56,MATCH($A16&"#"&3,Roster!$I$5:$I$56,0)),"")) -> Shawn Kwende | H16: =IF($A16="","",IFERROR(INDEX(Roster!$D$5:$D$56,MATCH($A16&"#"&4,Roster!$I$5:$I$56,0)),"")) -> Jared O'neal | I16: =IF($A16="","",IFERROR(INDEX(Roster!$D$5:$D$56,MATCH($A16&"#"&5,Roster!$I$5:$I$56,0)),"")) -> Brooke Salada | J16: =IF($A16="","",IFERROR(INDEX(Roster!$D$5:$D$56,MATCH($A16&"#"&6,Roster!$I$5:$I$56,0)),""))
A17: =IF(Groups!A13="","",Groups!A13) -> 4B | B17: =IF(A17="","",IF(Groups!B13="","Track not set",Groups!B13)) -> Oxygenation | C17: =IF(A17="","",Groups!C13) -> 5 | D17: =IF(A17="","",MIN(C17*$C$5,$C$6)) -> 80 | E17: =IF($A17="","",IFERROR(INDEX(Roster!$D$5:$D$56,MATCH($A17&"#"&1,Roster!$I$5:$I$56,0)),"")) -> Ashton Adams | F17: =IF($A17="","",IFERROR(INDEX(Roster!$D$5:$D$56,MATCH($A17&"#"&2,Roster!$I$5:$I$56,0)),"")) -> Jocelyn Gonzalez | G17: =IF($A17="","",IFERROR(INDEX(Roster!$D$5:$D$56,MATCH($A17&"#"&3,Roster!$I$5:$I$56,0)),"")) -> Michelle Gutierrez | H17: =IF($A17="","",IFERROR(INDEX(Roster!$D$5:$D$56,MATCH($A17&"#"&4,Roster!$I$5:$I$56,0)),"")) -> Jenna Koestler | I17: =IF($A17="","",IFERROR(INDEX(Roster!$D$5:$D$56,MATCH($A17&"#"&5,Roster!$I$5:$I$56,0)),"")) -> Roman Romashkin | J17: =IF($A17="","",IFERROR(INDEX(Roster!$D$5:$D$56,MATCH($A17&"#"&6,Roster!$I$5:$I$56,0)),""))
A18: =IF(Groups!A14="","",Groups!A14) -> 5B | B18: =IF(A18="","",IF(Groups!B14="","Track not set",Groups!B14)) -> Oxygenation | C18: =IF(A18="","",Groups!C14) -> 4 | D18: =IF(A18="","",MIN(C18*$C$5,$C$6)) -> 80 | E18: =IF($A18="","",IFERROR(INDEX(Roster!$D$5:$D$56,MATCH($A18&"#"&1,Roster!$I$5:$I$56,0)),"")) -> Brisa Colunga | F18: =IF($A18="","",IFERROR(INDEX(Roster!$D$5:$D$56,MATCH($A18&"#"&2,Roster!$I$5:$I$56,0)),"")) -> Alyssa Jasso | G18: =IF($A18="","",IFERROR(INDEX(Roster!$D$5:$D$56,MATCH($A18&"#"&3,Roster!$I$5:$I$56,0)),"")) -> Valeria Leon | H18: =IF($A18="","",IFERROR(INDEX(Roster!$D$5:$D$56,MATCH($A18&"#"&4,Roster!$I$5:$I$56,0)),"")) -> Haylee Senior | I18: =IF($A18="","",IFERROR(INDEX(Roster!$D$5:$D$56,MATCH($A18&"#"&5,Roster!$I$5:$I$56,0)),"")) | J18: =IF($A18="","",IFERROR(INDEX(Roster!$D$5:$D$56,MATCH($A18&"#"&6,Roster!$I$5:$I$56,0)),""))
A19: =IF(Groups!A15="","",Groups!A15) -> 6B | B19: =IF(A19="","",IF(Groups!B15="","Track not set",Groups!B15)) -> Oxygenation | C19: =IF(A19="","",Groups!C15) -> 4 | D19: =IF(A19="","",MIN(C19*$C$5,$C$6)) -> 80 | E19: =IF($A19="","",IFERROR(INDEX(Roster!$D$5:$D$56,MATCH($A19&"#"&1,Roster!$I$5:$I$56,0)),"")) -> Maryam Ka | F19: =IF($A19="","",IFERROR(INDEX(Roster!$D$5:$D$56,MATCH($A19&"#"&2,Roster!$I$5:$I$56,0)),"")) -> Daniela Osorio | G19: =IF($A19="","",IFERROR(INDEX(Roster!$D$5:$D$56,MATCH($A19&"#"&3,Roster!$I$5:$I$56,0)),"")) -> Yasmine Padilla | H19: =IF($A19="","",IFERROR(INDEX(Roster!$D$5:$D$56,MATCH($A19&"#"&4,Roster!$I$5:$I$56,0)),"")) -> Hayley Tarin | I19: =IF($A19="","",IFERROR(INDEX(Roster!$D$5:$D$56,MATCH($A19&"#"&5,Roster!$I$5:$I$56,0)),"")) | J19: =IF($A19="","",IFERROR(INDEX(Roster!$D$5:$D$56,MATCH($A19&"#"&6,Roster!$I$5:$I$56,0)),""))
A20: =IF(Groups!A16="","",Groups!A16) | B20: =IF(A20="","",IF(Groups!B16="","Track not set",Groups!B16)) | C20: =IF(A20="","",Groups!C16) | D20: =IF(A20="","",MIN(C20*$C$5,$C$6)) | E20: =IF($A20="","",IFERROR(INDEX(Roster!$D$5:$D$56,MATCH($A20&"#"&1,Roster!$I$5:$I$56,0)),"")) | F20: =IF($A20="","",IFERROR(INDEX(Roster!$D$5:$D$56,MATCH($A20&"#"&2,Roster!$I$5:$I$56,0)),"")) | G20: =IF($A20="","",IFERROR(INDEX(Roster!$D$5:$D$56,MATCH($A20&"#"&3,Roster!$I$5:$I$56,0)),"")) | H20: =IF($A20="","",IFERROR(INDEX(Roster!$D$5:$D$56,MATCH($A20&"#"&4,Roster!$I$5:$I$56,0)),"")) | I20: =IF($A20="","",IFERROR(INDEX(Roster!$D$5:$D$56,MATCH($A20&"#"&5,Roster!$I$5:$I$56,0)),"")) | J20: =IF($A20="","",IFERROR(INDEX(Roster!$D$5:$D$56,MATCH($A20&"#"&6,Roster!$I$5:$I$56,0)),""))
A21: =IF(Groups!A17="","",Groups!A17) | B21: =IF(A21="","",IF(Groups!B17="","Track not set",Groups!B17)) | C21: =IF(A21="","",Groups!C17) | D21: =IF(A21="","",MIN(C21*$C$5,$C$6)) | E21: =IF($A21="","",IFERROR(INDEX(Roster!$D$5:$D$56,MATCH($A21&"#"&1,Roster!$I$5:$I$56,0)),"")) | F21: =IF($A21="","",IFERROR(INDEX(Roster!$D$5:$D$56,MATCH($A21&"#"&2,Roster!$I$5:$I$56,0)),"")) | G21: =IF($A21="","",IFERROR(INDEX(Roster!$D$5:$D$56,MATCH($A21&"#"&3,Roster!$I$5:$I$56,0)),"")) | H21: =IF($A21="","",IFERROR(INDEX(Roster!$D$5:$D$56,MATCH($A21&"#"&4,Roster!$I$5:$I$56,0)),"")) | I21: =IF($A21="","",IFERROR(INDEX(Roster!$D$5:$D$56,MATCH($A21&"#"&5,Roster!$I$5:$I$56,0)),"")) | J21: =IF($A21="","",IFERROR(INDEX(Roster!$D$5:$D$56,MATCH($A21&"#"&6,Roster!$I$5:$I$56,0)),""))
A23: Methylene Blue Removal (Project A — DREAM) | C23: =SUMIF($B$9:$B$21,"Methylene Blue Removal",$C$9:$C$21) -> 24 | D23: =SUMIF($B$9:$B$21,"Methylene Blue Removal",$D$9:$D$21) -> 400
A24: Oxygenation (Project B — BOOST) | C24: =SUMIF($B$9:$B$21,"Oxygenation",$C$9:$C$21) -> 28 | D24: =SUMIF($B$9:$B$21,"Oxygenation",$D$9:$D$21) -> 480
A25: All groups | C25: =SUM(C9:C21) -> 52 | D25: =SUM(D9:D21) -> 880
A27: To move a student, change their group on the Roster tab (column E); this page updates. Every group has 4–5 students, so each reaches the $80 cap.

Sheet Quiz 1 Grades
A1: Quiz 1 — Grades by Student
A2: Blue cells = scores you type. Subtotals, total, %, band, rank and status are formulas. Rows turn yellow when a student has no scores. | R2: Performance bands
R3: Strong (green) if total ≥ | S3: 40
A4: Student | C4: ="Problem 1 ("&G5&" pts)" -> Problem 1 (35 pts) | H4: ="Problem 2 ("&K5&" pts)" -> Problem 2 (15 pts) | L4: Results | R4: Satisfactory (yellow) if total ≥ | S4: 26
B5: Max points | C5: 10 | D5: 15 | E5: 5 | F5: 5 | G5: =SUM(C5:F5) -> 35 | H5: 5 | I5: 5 | J5: 5 | K5: =SUM(H5:J5) -> 15 | L5: =G5+K5 -> 50 | R5: Needs support (red) if total < | S5: =S4 -> 26
A6: # | B6: Student Name | C6: 1.1 | D6: 1.2 | E6: 1.3 A | F6: 1.3 B | G6: P1 Total | H6: 2.1 | I6: 2.2 | J6: 2.3 | K6: P2 Total | L6: TOTAL | M6: % | N6: Performance | O6: Rank | P6: Status
A7: 1 | B7: =IFERROR(INDEX(Roster!$D$5:$D$56,MATCH($A7,Roster!$A$5:$A$56,0)),"(not on roster)") -> David Abagwe | C7: 8 | D7: 13 | E7: 4 | F7: 4 | G7: =IF(COUNT(C7:F7)=0,"",SUM(C7:F7)) -> 29 | H7: 5 | I7: 5 | J7: 5 | K7: =IF(COUNT(H7:J7)=0,"",SUM(H7:J7)) -> 15 | L7: =IF(COUNT(C7:F7,H7:J7)=COUNT($C$5:$F$5,$H$5:$J$5),SUM(C7:F7,H7:J7),"") -> 44 | M7: =IF(ISNUMBER(L7),L7/$L$5,"") -> 0.88 | N7: =IF(ISNUMBER(L7),IF(L7>=$S$3,"Strong",IF(L7>=$S$4,"Satisfactory","Needs support")),"") -> Strong | O7: =IF(ISNUMBER(L7),RANK(L7,$L$7:$L$58,0),"") -> 14 | P7: =IF(COUNT(C7:F7,H7:J7)=0,"Missing",IF(COUNT(C7:F7,H7:J7)<COUNT($C$5:$F$5,$H$5:$J$5),"Incomplete","Graded")) -> Graded
A8: 2 | B8: =IFERROR(INDEX(Roster!$D$5:$D$56,MATCH($A8,Roster!$A$5:$A$56,0)),"(not on roster)") -> Sonu Acharya | C8: 0 | D8: 5 | E8: 3 | F8: 3 | G8: =IF(COUNT(C8:F8)=0,"",SUM(C8:F8)) -> 11 | H8: 5 | I8: 5 | J8: 0 | K8: =IF(COUNT(H8:J8)=0,"",SUM(H8:J8)) -> 10 | L8: =IF(COUNT(C8:F8,H8:J8)=COUNT($C$5:$F$5,$H$5:$J$5),SUM(C8:F8,H8:J8),"") -> 21 | M8: =IF(ISNUMBER(L8),L8/$L$5,"") -> 0.42 | N8: =IF(ISNUMBER(L8),IF(L8>=$S$3,"Strong",IF(L8>=$S$4,"Satisfactory","Needs support")),"") -> Needs support | O8: =IF(ISNUMBER(L8),RANK(L8,$L$7:$L$58,0),"") -> 49 | P8: =IF(COUNT(C8:F8,H8:J8)=0,"Missing",IF(COUNT(C8:F8,H8:J8)<COUNT($C$5:$F$5,$H$5:$J$5),"Incomplete","Graded")) -> Graded
A9: 3 | B9: =IFERROR(INDEX(Roster!$D$5:$D$56,MATCH($A9,Roster!$A$5:$A$56,0)),"(not on roster)") -> Ashton Adams | C9: 8 | D9: 10 | E9: 5 | F9: 5 | G9: =IF(COUNT(C9:F9)=0,"",SUM(C9:F9)) -> 28 | H9: 5 | I9: 5 | J9: 5 | K9: =IF(COUNT(H9:J9)=0,"",SUM(H9:J9)) -> 15 | L9: =IF(COUNT(C9:F9,H9:J9)=COUNT($C$5:$F$5,$H$5:$J$5),SUM(C9:F9,H9:J9),"") -> 43 | M9: =IF(ISNUMBER(L9),L9/$L$5,"") -> 0.86 | N9: =IF(ISNUMBER(L9),IF(L9>=$S$3,"Strong",IF(L9>=$S$4,"Satisfactory","Needs support")),"") -> Strong | O9: =IF(ISNUMBER(L9),RANK(L9,$L$7:$L$58,0),"") -> 17 | P9: =IF(COUNT(C9:F9,H9:J9)=0,"Missing",IF(COUNT(C9:F9,H9:J9)<COUNT($C$5:$F$5,$H$5:$J$5),"Incomplete","Graded")) -> Graded
A10: 4 | B10: =IFERROR(INDEX(Roster!$D$5:$D$56,MATCH($A10,Roster!$A$5:$A$56,0)),"(not on roster)") -> Hayden Albert | C10: 5 | D10: 15 | E10: 4 | F10: 4 | G10: =IF(COUNT(C10:F10)=0,"",SUM(C10:F10)) -> 28 | H10: 5 | I10: 5 | J10: 5 | K10: =IF(COUNT(H10:J10)=0,"",SUM(H10:J10)) -> 15 | L10: =IF(COUNT(C10:F10,H10:J10)=COUNT($C$5:$F$5,$H$5:$J$5),SUM(C10:F10,H10:J10),"") -> 43 | M10: =IF(ISNUMBER(L10),L10/$L$5,"") -> 0.86 | N10: =IF(ISNUMBER(L10),IF(L10>=$S$3,"Strong",IF(L10>=$S$4,"Satisfactory","Needs support")),"") -> Strong | O10: =IF(ISNUMBER(L10),RANK(L10,$L$7:$L$58,0),"") -> 17 | P10: =IF(COUNT(C10:F10,H10:J10)=0,"Missing",IF(COUNT(C10:F10,H10:J10)<COUNT($C$5:$F$5,$H$5:$J$5),"Incomplete","Graded")) -> Graded
A11: 5 | B11: =IFERROR(INDEX(Roster!$D$5:$D$56,MATCH($A11,Roster!$A$5:$A$56,0)),"(not on roster)") -> Lani Allen | C11: 10 | D11: 15 | E11: 5 | F11: 5 | G11: =IF(COUNT(C11:F11)=0,"",SUM(C11:F11)) -> 35 | H11: 5 | I11: 5 | J11: 5 | K11: =IF(COUNT(H11:J11)=0,"",SUM(H11:J11)) -> 15 | L11: =IF(COUNT(C11:F11,H11:J11)=COUNT($C$5:$F$5,$H$5:$J$5),SUM(C11:F11,H11:J11),"") -> 50 | M11: =IF(ISNUMBER(L11),L11/$L$5,"") -> 1 | N11: =IF(ISNUMBER(L11),IF(L11>=$S$3,"Strong",IF(L11>=$S$4,"Satisfactory","Needs support")),"") -> Strong | O11: =IF(ISNUMBER(L11),RANK(L11,$L$7:$L$58,0),"") -> 1 | P11: =IF(COUNT(C11:F11,H11:J11)=0,"Missing",IF(COUNT(C11:F11,H11:J11)<COUNT($C$5:$F$5,$H$5:$J$5),"Incomplete","Graded")) -> Graded
A12: 6 | B12: =IFERROR(INDEX(Roster!$D$5:$D$56,MATCH($A12,Roster!$A$5:$A$56,0)),"(not on roster)") -> John David Andrade | C12: 8 | D12: 10 | E12: 5 | F12: 4 | G12: =IF(COUNT(C12:F12)=0,"",SUM(C12:F12)) -> 27 | H12: 0 | I12: 0 | J12: 5 | K12: =IF(COUNT(H12:J12)=0,"",SUM(H12:J12)) -> 5 | L12: =IF(COUNT(C12:F12,H12:J12)=COUNT($C$5:$F$5,$H$5:$J$5),SUM(C12:F12,H12:J12),"") -> 32 | M12: =IF(ISNUMBER(L12),L12/$L$5,"") -> 0.64 | N12: =IF(ISNUMBER(L12),IF(L12>=$S$3,"Strong",IF(L12>=$S$4,"Satisfactory","Needs support")),"") -> Satisfactory | O12: =IF(ISNUMBER(L12),RANK(L12,$L$7:$L$58,0),"") -> 37 | P12: =IF(COUNT(C12:F12,H12:J12)=0,"Missing",IF(COUNT(C12:F12,H12:J12)<COUNT($C$5:$F$5,$H$5:$J$5),"Incomplete","Graded")) -> Graded
A13: 7 | B13: =IFERROR(INDEX(Roster!$D$5:$D$56,MATCH($A13,Roster!$A$5:$A$56,0)),"(not on roster)") -> Landon Atkins | C13: 5 | D13: 5 | E13: 3 | F13: 3 | G13: =IF(COUNT(C13:F13)=0,"",SUM(C13:F13)) -> 16 | H13: 5 | I13: 0 | J13: 5 | K13: =IF(COUNT(H13:J13)=0,"",SUM(H13:J13)) -> 10 | L13: =IF(COUNT(C13:F13,H13:J13)=COUNT($C$5:$F$5,$H$5:$J$5),SUM(C13:F13,H13:J13),"") -> 26 | M13: =IF(ISNUMBER(L13),L13/$L$5,"") -> 0.52 | N13: =IF(ISNUMBER(L13),IF(L13>=$S$3,"Strong",IF(L13>=$S$4,"Satisfactory","Needs support")),"") -> Satisfactory | O13: =IF(ISNUMBER(L13),RANK(L13,$L$7:$L$58,0),"") -> 44 | P13: =IF(COUNT(C13:F13,H13:J13)=0,"Missing",IF(COUNT(C13:F13,H13:J13)<COUNT($C$5:$F$5,$H$5:$J$5),"Incomplete","Graded")) -> Graded
A14: 8 | B14: =IFERROR(INDEX(Roster!$D$5:$D$56,MATCH($A14,Roster!$A$5:$A$56,0)),"(not on roster)") -> Ryan Borkland | C14: 10 | D14: 15 | E14: 3 | F14: 3 | G14: =IF(COUNT(C14:F14)=0,"",SUM(C14:F14)) -> 31 | H14: 5 | I14: 5 | J14: 5 | K14: =IF(COUNT(H14:J14)=0,"",SUM(H14:J14)) -> 15 | L14: =IF(COUNT(C14:F14,H14:J14)=COUNT($C$5:$F$5,$H$5:$J$5),SUM(C14:F14,H14:J14),"") -> 46 | M14: =IF(ISNUMBER(L14),L14/$L$5,"") -> 0.92 | N14: =IF(ISNUMBER(L14),IF(L14>=$S$3,"Strong",IF(L14>=$S$4,"Satisfactory","Needs support")),"") -> Strong | O14: =IF(ISNUMBER(L14),RANK(L14,$L$7:$L$58,0),"") -> 8 | P14: =IF(COUNT(C14:F14,H14:J14)=0,"Missing",IF(COUNT(C14:F14,H14:J14)<COUNT($C$5:$F$5,$H$5:$J$5),"Incomplete","Graded")) -> Graded
A15: 9 | B15: =IFERROR(INDEX(Roster!$D$5:$D$56,MATCH($A15,Roster!$A$5:$A$56,0)),"(not on roster)") -> Jermy Brown | C15: 8 | D15: 15 | E15: 3 | F15: 3 | G15: =IF(COUNT(C15:F15)=0,"",SUM(C15:F15)) -> 29 | H15: 5 | I15: 5 | J15: 5 | K15: =IF(COUNT(H15:J15)=0,"",SUM(H15:J15)) -> 15 | L15: =IF(COUNT(C15:F15,H15:J15)=COUNT($C$5:$F$5,$H$5:$J$5),SUM(C15:F15,H15:J15),"") -> 44 | M15: =IF(ISNUMBER(L15),L15/$L$5,"") -> 0.88 | N15: =IF(ISNUMBER(L15),IF(L15>=$S$3,"Strong",IF(L15>=$S$4,"Satisfactory","Needs support")),"") -> Strong | O15: =IF(ISNUMBER(L15),RANK(L15,$L$7:$L$58,0),"") -> 14 | P15: =IF(COUNT(C15:F15,H15:J15)=0,"Missing",IF(COUNT(C15:F15,H15:J15)<COUNT($C$5:$F$5,$H$5:$J$5),"Incomplete","Graded")) -> Graded
A16: 10 | B16: =IFERROR(INDEX(Roster!$D$5:$D$56,MATCH($A16,Roster!$A$5:$A$56,0)),"(not on roster)") -> Eric Calderon | C16: 3 | D16: 15 | E16: 5 | F16: 5 | G16: =IF(COUNT(C16:F16)=0,"",SUM(C16:F16)) -> 28 | H16: 5 | I16: 0 | J16: 5 | K16: =IF(COUNT(H16:J16)=0,"",SUM(H16:J16)) -> 10 | L16: =IF(COUNT(C16:F16,H16:J16)=COUNT($C$5:$F$5,$H$5:$J$5),SUM(C16:F16,H16:J16),"") -> 38 | M16: =IF(ISNUMBER(L16),L16/$L$5,"") -> 0.76 | N16: =IF(ISNUMBER(L16),IF(L16>=$S$3,"Strong",IF(L16>=$S$4,"Satisfactory","Needs support")),"") -> Satisfactory | O16: =IF(ISNUMBER(L16),RANK(L16,$L$7:$L$58,0),"") -> 29 | P16: =IF(COUNT(C16:F16,H16:J16)=0,"Missing",IF(COUNT(C16:F16,H16:J16)<COUNT($C$5:$F$5,$H$5:$J$5),"Incomplete","Graded")) -> Graded
A17: 11 | B17: =IFERROR(INDEX(Roster!$D$5:$D$56,MATCH($A17,Roster!$A$5:$A$56,0)),"(not on roster)") -> Angel Camarillo | C17: 2 | D17: 8 | E17: 3 | F17: 3 | G17: =IF(COUNT(C17:F17)=0,"",SUM(C17:F17)) -> 16 | H17: 5 | I17: 0 | J17: 5 | K17: =IF(COUNT(H17:J17)=0,"",SUM(H17:J17)) -> 10 | L17: =IF(COUNT(C17:F17,H17:J17)=COUNT($C$5:$F$5,$H$5:$J$5),SUM(C17:F17,H17:J17),"") -> 26 | M17: =IF(ISNUMBER(L17),L17/$L$5,"") -> 0.52 | N17: =IF(ISNUMBER(L17),IF(L17>=$S$3,"Strong",IF(L17>=$S$4,"Satisfactory","Needs support")),"") -> Satisfactory | O17: =IF(ISNUMBER(L17),RANK(L17,$L$7:$L$58,0),"") -> 44 | P17: =IF(COUNT(C17:F17,H17:J17)=0,"Missing",IF(COUNT(C17:F17,H17:J17)<COUNT($C$5:$F$5,$H$5:$J$5),"Incomplete","Graded")) -> Graded
A18: 12 | B18: =IFERROR(INDEX(Roster!$D$5:$D$56,MATCH($A18,Roster!$A$5:$A$56,0)),"(not on roster)") -> Gavin Cappel | G18: =IF(COUNT(C18:F18)=0,"",SUM(C18:F18)) | K18: =IF(COUNT(H18:J18)=0,"",SUM(H18:J18)) | L18: =IF(COUNT(C18:F18,H18:J18)=COUNT($C$5:$F$5,$H$5:$J$5),SUM(C18:F18,H18:J18),"") | M18: =IF(ISNUMBER(L18),L18/$L$5,"") | N18: =IF(ISNUMBER(L18),IF(L18>=$S$3,"Strong",IF(L18>=$S$4,"Satisfactory","Needs support")),"") | O18: =IF(ISNUMBER(L18),RANK(L18,$L$7:$L$58,0),"") | P18: =IF(COUNT(C18:F18,H18:J18)=0,"Missing",IF(COUNT(C18:F18,H18:J18)<COUNT($C$5:$F$5,$H$5:$J$5),"Incomplete","Graded")) -> Missing
A19: 13 | B19: =IFERROR(INDEX(Roster!$D$5:$D$56,MATCH($A19,Roster!$A$5:$A$56,0)),"(not on roster)") -> Venditha Chelikani | C19: 10 | D19: 15 | E19: 4 | F19: 4 | G19: =IF(COUNT(C19:F19)=0,"",SUM(C19:F19)) -> 33 | H19: 5 | I19: 5 | J19: 5 | K19: =IF(COUNT(H19:J19)=0,"",SUM(H19:J19)) -> 15 | L19: =IF(COUNT(C19:F19,H19:J19)=COUNT($C$5:$F$5,$H$5:$J$5),SUM(C19:F19,H19:J19),"") -> 48 | M19: =IF(ISNUMBER(L19),L19/$L$5,"") -> 0.96 | N19: =IF(ISNUMBER(L19),IF(L19>=$S$3,"Strong",IF(L19>=$S$4,"Satisfactory","Needs support")),"") -> Strong | O19: =IF(ISNUMBER(L19),RANK(L19,$L$7:$L$58,0),"") -> 6 | P19: =IF(COUNT(C19:F19,H19:J19)=0,"Missing",IF(COUNT(C19:F19,H19:J19)<COUNT($C$5:$F$5,$H$5:$J$5),"Incomplete","Graded")) -> Graded
A20: 14 | B20: =IFERROR(INDEX(Roster!$D$5:$D$56,MATCH($A20,Roster!$A$5:$A$56,0)),"(not on roster)") -> Brisa Colunga | C20: 10 | D20: 15 | E20: 4 | F20: 4 | G20: =IF(COUNT(C20:F20)=0,"",SUM(C20:F20)) -> 33 | H20: 5 | I20: 0 | J20: 5 | K20: =IF(COUNT(H20:J20)=0,"",SUM(H20:J20)) -> 10 | L20: =IF(COUNT(C20:F20,H20:J20)=COUNT($C$5:$F$5,$H$5:$J$5),SUM(C20:F20,H20:J20),"") -> 43 | M20: =IF(ISNUMBER(L20),L20/$L$5,"") -> 0.86 | N20: =IF(ISNUMBER(L20),IF(L20>=$S$3,"Strong",IF(L20>=$S$4,"Satisfactory","Needs support")),"") -> Strong | O20: =IF(ISNUMBER(L20),RANK(L20,$L$7:$L$58,0),"") -> 17 | P20: =IF(COUNT(C20:F20,H20:J20)=0,"Missing",IF(COUNT(C20:F20,H20:J20)<COUNT($C$5:$F$5,$H$5:$J$5),"Incomplete","Graded")) -> Graded
A21: 15 | B21: =IFERROR(INDEX(Roster!$D$5:$D$56,MATCH($A21,Roster!$A$5:$A$56,0)),"(not on roster)") -> Axel Cruz-Hernandez | C21: 3 | D21: 8 | E21: 4 | F21: 4 | G21: =IF(COUNT(C21:F21)=0,"",SUM(C21:F21)) -> 19 | H21: 5 | I21: 0 | J21: 5 | K21: =IF(COUNT(H21:J21)=0,"",SUM(H21:J21)) -> 10 | L21: =IF(COUNT(C21:F21,H21:J21)=COUNT($C$5:$F$5,$H$5:$J$5),SUM(C21:F21,H21:J21),"") -> 29 | M21: =IF(ISNUMBER(L21),L21/$L$5,"") -> 0.58 | N21: =IF(ISNUMBER(L21),IF(L21>=$S$3,"Strong",IF(L21>=$S$4,"Satisfactory","Needs support")),"") -> Satisfactory | O21: =IF(ISNUMBER(L21),RANK(L21,$L$7:$L$58,0),"") -> 38 | P21: =IF(COUNT(C21:F21,H21:J21)=0,"Missing",IF(COUNT(C21:F21,H21:J21)<COUNT($C$5:$F$5,$H$5:$J$5),"Incomplete","Graded")) -> Graded
A22: 16 | B22: =IFERROR(INDEX(Roster!$D$5:$D$56,MATCH($A22,Roster!$A$5:$A$56,0)),"(not on roster)") -> Devin Cuellar | C22: 8 | D22: 15 | E22: 5 | F22: 5 | G22: =IF(COUNT(C22:F22)=0,"",SUM(C22:F22)) -> 33 | H22: 5 | I22: 0 | J22: 5 | K22: =IF(COUNT(H22:J22)=0,"",SUM(H22:J22)) -> 10 | L22: =IF(COUNT(C22:F22,H22:J22)=COUNT($C$5:$F$5,$H$5:$J$5),SUM(C22:F22,H22:J22),"") -> 43 | M22: =IF(ISNUMBER(L22),L22/$L$5,"") -> 0.86 | N22: =IF(ISNUMBER(L22),IF(L22>=$S$3,"Strong",IF(L22>=$S$4,"Satisfactory","Needs support")),"") -> Strong | O22: =IF(ISNUMBER(L22),RANK(L22,$L$7:$L$58,0),"") -> 17 | P22: =IF(COUNT(C22:F22,H22:J22)=0,"Missing",IF(COUNT(C22:F22,H22:J22)<COUNT($C$5:$F$5,$H$5:$J$5),"Incomplete","Graded")) -> Graded
A23: 17 | B23: =IFERROR(INDEX(Roster!$D$5:$D$56,MATCH($A23,Roster!$A$5:$A$56,0)),"(not on roster)") -> Mia Cuellar | C23: 3 | D23: 5 | E23: 4 | F23: 4 | G23: =IF(COUNT(C23:F23)=0,"",SUM(C23:F23)) -> 16 | H23: 0 | I23: 5 | J23: 5 | K23: =IF(COUNT(H23:J23)=0,"",SUM(H23:J23)) -> 10 | L23: =IF(COUNT(C23:F23,H23:J23)=COUNT($C$5:$F$5,$H$5:$J$5),SUM(C23:F23,H23:J23),"") -> 26 | M23: =IF(ISNUMBER(L23),L23/$L$5,"") -> 0.52 | N23: =IF(ISNUMBER(L23),IF(L23>=$S$3,"Strong",IF(L23>=$S$4,"Satisfactory","Needs support")),"") -> Satisfactory | O23: =IF(ISNUMBER(L23),RANK(L23,$L$7:$L$58,0),"") -> 44 | P23: =IF(COUNT(C23:F23,H23:J23)=0,"Missing",IF(COUNT(C23:F23,H23:J23)<COUNT($C$5:$F$5,$H$5:$J$5),"Incomplete","Graded")) -> Graded
A24: 18 | B24: =IFERROR(INDEX(Roster!$D$5:$D$56,MATCH($A24,Roster!$A$5:$A$56,0)),"(not on roster)") -> Trevin Cutrer | C24: 4 | D24: 8 | E24: 3 | F24: 3 | G24: =IF(COUNT(C24:F24)=0,"",SUM(C24:F24)) -> 18 | H24: 0 | I24: 5 | J24: 5 | K24: =IF(COUNT(H24:J24)=0,"",SUM(H24:J24)) -> 10 | L24: =IF(COUNT(C24:F24,H24:J24)=COUNT($C$5:$F$5,$H$5:$J$5),SUM(C24:F24,H24:J24),"") -> 28 | M24: =IF(ISNUMBER(L24),L24/$L$5,"") -> 0.56 | N24: =IF(ISNUMBER(L24),IF(L24>=$S$3,"Strong",IF(L24>=$S$4,"Satisfactory","Needs support")),"") -> Satisfactory | O24: =IF(ISNUMBER(L24),RANK(L24,$L$7:$L$58,0),"") -> 41 | P24: =IF(COUNT(C24:F24,H24:J24)=0,"Missing",IF(COUNT(C24:F24,H24:J24)<COUNT($C$5:$F$5,$H$5:$J$5),"Incomplete","Graded")) -> Graded
A25: 19 | B25: =IFERROR(INDEX(Roster!$D$5:$D$56,MATCH($A25,Roster!$A$5:$A$56,0)),"(not on roster)") -> Elizabeth Dillah | C25: 8 | D25: 5 | E25: 5 | F25: 5 | G25: =IF(COUNT(C25:F25)=0,"",SUM(C25:F25)) -> 23 | H25: 0 | I25: 0 | J25: 0 | K25: =IF(COUNT(H25:J25)=0,"",SUM(H25:J25)) -> 0 | L25: =IF(COUNT(C25:F25,H25:J25)=COUNT($C$5:$F$5,$H$5:$J$5),SUM(C25:F25,H25:J25),"") -> 23 | M25: =IF(ISNUMBER(L25),L25/$L$5,"") -> 0.46 | N25: =IF(ISNUMBER(L25),IF(L25>=$S$3,"Strong",IF(L25>=$S$4,"Satisfactory","Needs support")),"") -> Needs support | O25: =IF(ISNUMBER(L25),RANK(L25,$L$7:$L$58,0),"") -> 47 | P25: =IF(COUNT(C25:F25,H25:J25)=0,"Missing",IF(COUNT(C25:F25,H25:J25)<COUNT($C$5:$F$5,$H$5:$J$5),"Incomplete","Graded")) -> Graded
A26: 20 | B26: =IFERROR(INDEX(Roster!$D$5:$D$56,MATCH($A26,Roster!$A$5:$A$56,0)),"(not on roster)") -> Jack Elsas | C26: 10 | D26: 15 | E26: 5 | F26: 5 | G26: =IF(COUNT(C26:F26)=0,"",SUM(C26:F26)) -> 35 | H26: 5 | I26: 5 | J26: 5 | K26: =IF(COUNT(H26:J26)=0,"",SUM(H26:J26)) -> 15 | L26: =IF(COUNT(C26:F26,H26:J26)=COUNT($C$5:$F$5,$H$5:$J$5),SUM(C26:F26,H26:J26),"") -> 50 | M26: =IF(ISNUMBER(L26),L26/$L$5,"") -> 1 | N26: =IF(ISNUMBER(L26),IF(L26>=$S$3,"Strong",IF(L26>=$S$4,"Satisfactory","Needs support")),"") -> Strong | O26: =IF(ISNUMBER(L26),RANK(L26,$L$7:$L$58,0),"") -> 1 | P26: =IF(COUNT(C26:F26,H26:J26)=0,"Missing",IF(COUNT(C26:F26,H26:J26)<COUNT($C$5:$F$5,$H$5:$J$5),"Incomplete","Graded")) -> Graded
A27: 21 | B27: =IFERROR(INDEX(Roster!$D$5:$D$56,MATCH($A27,Roster!$A$5:$A$56,0)),"(not on roster)") -> Connor Felux | C27: 8 | D27: 15 | E27: 4 | F27: 4 | G27: =IF(COUNT(C27:F27)=0,"",SUM(C27:F27)) -> 31 | H27: 5 | I27: 5 | J27: 5 | K27: =IF(COUNT(H27:J27)=0,"",SUM(H27:J27)) -> 15 | L27: =IF(COUNT(C27:F27,H27:J27)=COUNT($C$5:$F$5,$H$5:$J$5),SUM(C27:F27,H27:J27),"") -> 46 | M27: =IF(ISNUMBER(L27),L27/$L$5,"") -> 0.92 | N27: =IF(ISNUMBER(L27),IF(L27>=$S$3,"Strong",IF(L27>=$S$4,"Satisfactory","Needs support")),"") -> Strong | O27: =IF(ISNUMBER(L27),RANK(L27,$L$7:$L$58,0),"") -> 8 | P27: =IF(COUNT(C27:F27,H27:J27)=0,"Missing",IF(COUNT(C27:F27,H27:J27)<COUNT($C$5:$F$5,$H$5:$J$5),"Incomplete","Graded")) -> Graded
A28: 22 | B28: =IFERROR(INDEX(Roster!$D$5:$D$56,MATCH($A28,Roster!$A$5:$A$56,0)),"(not on roster)") -> Hunter Gates | C28: 8 | D28: 15 | E28: 4 | F28: 4 | G28: =IF(COUNT(C28:F28)=0,"",SUM(C28:F28)) -> 31 | H28: 5 | I28: 5 | J28: 5 | K28: =IF(COUNT(H28:J28)=0,"",SUM(H28:J28)) -> 15 | L28: =IF(COUNT(C28:F28,H28:J28)=COUNT($C$5:$F$5,$H$5:$J$5),SUM(C28:F28,H28:J28),"") -> 46 | M28: =IF(ISNUMBER(L28),L28/$L$5,"") -> 0.92 | N28: =IF(ISNUMBER(L28),IF(L28>=$S$3,"Strong",IF(L28>=$S$4,"Satisfactory","Needs support")),"") -> Strong | O28: =IF(ISNUMBER(L28),RANK(L28,$L$7:$L$58,0),"") -> 8 | P28: =IF(COUNT(C28:F28,H28:J28)=0,"Missing",IF(COUNT(C28:F28,H28:J28)<COUNT($C$5:$F$5,$H$5:$J$5),"Incomplete","Graded")) -> Graded
A29: 23 | B29: =IFERROR(INDEX(Roster!$D$5:$D$56,MATCH($A29,Roster!$A$5:$A$56,0)),"(not on roster)") -> Brinda Gayen | C29: 5 | D29: 10 | E29: 4 | F29: 4 | G29: =IF(COUNT(C29:F29)=0,"",SUM(C29:F29)) -> 23 | H29: 5 | I29: 0 | J29: 0 | K29: =IF(COUNT(H29:J29)=0,"",SUM(H29:J29)) -> 5 | L29: =IF(COUNT(C29:F29,H29:J29)=COUNT($C$5:$F$5,$H$5:$J$5),SUM(C29:F29,H29:J29),"") -> 28 | M29: =IF(ISNUMBER(L29),L29/$L$5,"") -> 0.56 | N29: =IF(ISNUMBER(L29),IF(L29>=$S$3,"Strong",IF(L29>=$S$4,"Satisfactory","Needs support")),"") -> Satisfactory | O29: =IF(ISNUMBER(L29),RANK(L29,$L$7:$L$58,0),"") -> 41 | P29: =IF(COUNT(C29:F29,H29:J29)=0,"Missing",IF(COUNT(C29:F29,H29:J29)<COUNT($C$5:$F$5,$H$5:$J$5),"Incomplete","Graded")) -> Graded
A30: 24 | B30: =IFERROR(INDEX(Roster!$D$5:$D$56,MATCH($A30,Roster!$A$5:$A$56,0)),"(not on roster)") -> Victoria Gaytan | C30: 8 | D30: 15 | E30: 4 | F30: 4 | G30: =IF(COUNT(C30:F30)=0,"",SUM(C30:F30)) -> 31 | H30: 5 | I30: 5 | J30: 5 | K30: =IF(COUNT(H30:J30)=0,"",SUM(H30:J30)) -> 15 | L30: =IF(COUNT(C30:F30,H30:J30)=COUNT($C$5:$F$5,$H$5:$J$5),SUM(C30:F30,H30:J30),"") -> 46 | M30: =IF(ISNUMBER(L30),L30/$L$5,"") -> 0.92 | N30: =IF(ISNUMBER(L30),IF(L30>=$S$3,"Strong",IF(L30>=$S$4,"Satisfactory","Needs support")),"") -> Strong | O30: =IF(ISNUMBER(L30),RANK(L30,$L$7:$L$58,0),"") -> 8 | P30: =IF(COUNT(C30:F30,H30:J30)=0,"Missing",IF(COUNT(C30:F30,H30:J30)<COUNT($C$5:$F$5,$H$5:$J$5),"Incomplete","Graded")) -> Graded
A31: 25 | B31: =IFERROR(INDEX(Roster!$D$5:$D$56,MATCH($A31,Roster!$A$5:$A$56,0)),"(not on roster)") -> Jocelyn Gonzalez | C31: 7 | D31: 15 | E31: 5 | F31: 5 | G31: =IF(COUNT(C31:F31)=0,"",SUM(C31:F31)) -> 32 | H31: 5 | I31: 0 | J31: 5 | K31: =IF(COUNT(H31:J31)=0,"",SUM(H31:J31)) -> 10 | L31: =IF(COUNT(C31:F31,H31:J31)=COUNT($C$5:$F$5,$H$5:$J$5),SUM(C31:F31,H31:J31),"") -> 42 | M31: =IF(ISNUMBER(L31),L31/$L$5,"") -> 0.84 | N31: =IF(ISNUMBER(L31),IF(L31>=$S$3,"Strong",IF(L31>=$S$4,"Satisfactory","Needs support")),"") -> Strong | O31: =IF(ISNUMBER(L31),RANK(L31,$L$7:$L$58,0),"") -> 22 | P31: =IF(COUNT(C31:F31,H31:J31)=0,"Missing",IF(COUNT(C31:F31,H31:J31)<COUNT($C$5:$F$5,$H$5:$J$5),"Incomplete","Graded")) -> Graded
A32: 26 | B32: =IFERROR(INDEX(Roster!$D$5:$D$56,MATCH($A32,Roster!$A$5:$A$56,0)),"(not on roster)") -> Michelle Gutierrez | G32: =IF(COUNT(C32:F32)=0,"",SUM(C32:F32)) | K32: =IF(COUNT(H32:J32)=0,"",SUM(H32:J32)) | L32: =IF(COUNT(C32:F32,H32:J32)=COUNT($C$5:$F$5,$H$5:$J$5),SUM(C32:F32,H32:J32),"") | M32: =IF(ISNUMBER(L32),L32/$L$5,"") | N32: =IF(ISNUMBER(L32),IF(L32>=$S$3,"Strong",IF(L32>=$S$4,"Satisfactory","Needs support")),"") | O32: =IF(ISNUMBER(L32),RANK(L32,$L$7:$L$58,0),"") | P32: =IF(COUNT(C32:F32,H32:J32)=0,"Missing",IF(COUNT(C32:F32,H32:J32)<COUNT($C$5:$F$5,$H$5:$J$5),"Incomplete","Graded")) -> Missing
A33: 27 | B33: =IFERROR(INDEX(Roster!$D$5:$D$56,MATCH($A33,Roster!$A$5:$A$56,0)),"(not on roster)") -> Rachel Holmes | C33: 3 | D33: 6 | E33: 4 | F33: 4 | G33: =IF(COUNT(C33:F33)=0,"",SUM(C33:F33)) -> 17 | H33: 5 | I33: 0 | J33: 5 | K33: =IF(COUNT(H33:J33)=0,"",SUM(H33:J33)) -> 10 | L33: =IF(COUNT(C33:F33,H33:J33)=COUNT($C$5:$F$5,$H$5:$J$5),SUM(C33:F33,H33:J33),"") -> 27 | M33: =IF(ISNUMBER(L33),L33/$L$5,"") -> 0.54 | N33: =IF(ISNUMBER(L33),IF(L33>=$S$3,"Strong",IF(L33>=$S$4,"Satisfactory","Needs support")),"") -> Satisfactory | O33: =IF(ISNUMBER(L33),RANK(L33,$L$7:$L$58,0),"") -> 43 | P33: =IF(COUNT(C33:F33,H33:J33)=0,"Missing",IF(COUNT(C33:F33,H33:J33)<COUNT($C$5:$F$5,$H$5:$J$5),"Incomplete","Graded")) -> Graded
A34: 28 | B34: =IFERROR(INDEX(Roster!$D$5:$D$56,MATCH($A34,Roster!$A$5:$A$56,0)),"(not on roster)") -> Emily Ickert | C34: 10 | D34: 15 | E34: 5 | F34: 5 | G34: =IF(COUNT(C34:F34)=0,"",SUM(C34:F34)) -> 35 | H34: 5 | I34: 5 | J34: 5 | K34: =IF(COUNT(H34:J34)=0,"",SUM(H34:J34)) -> 15 | L34: =IF(COUNT(C34:F34,H34:J34)=COUNT($C$5:$F$5,$H$5:$J$5),SUM(C34:F34,H34:J34),"") -> 50 | M34: =IF(ISNUMBER(L34),L34/$L$5,"") -> 1 | N34: =IF(ISNUMBER(L34),IF(L34>=$S$3,"Strong",IF(L34>=$S$4,"Satisfactory","Needs support")),"") -> Strong | O34: =IF(ISNUMBER(L34),RANK(L34,$L$7:$L$58,0),"") -> 1 | P34: =IF(COUNT(C34:F34,H34:J34)=0,"Missing",IF(COUNT(C34:F34,H34:J34)<COUNT($C$5:$F$5,$H$5:$J$5),"Incomplete","Graded")) -> Graded
A35: 29 | B35: =IFERROR(INDEX(Roster!$D$5:$D$56,MATCH($A35,Roster!$A$5:$A$56,0)),"(not on roster)") -> Mihal Jacob | C35: 5 | D35: 8 | E35: 4 | F35: 4 | G35: =IF(COUNT(C35:F35)=0,"",SUM(C35:F35)) -> 21 | H35: 5 | I35: 5 | J35: 5 | K35: =IF(COUNT(H35:J35)=0,"",SUM(H35:J35)) -> 15 | L35: =IF(COUNT(C35:F35,H35:J35)=COUNT($C$5:$F$5,$H$5:$J$5),SUM(C35:F35,H35:J35),"") -> 36 | M35: =IF(ISNUMBER(L35),L35/$L$5,"") -> 0.72 | N35: =IF(ISNUMBER(L35),IF(L35>=$S$3,"Strong",IF(L35>=$S$4,"Satisfactory","Needs support")),"") -> Satisfactory | O35: =IF(ISNUMBER(L35),RANK(L35,$L$7:$L$58,0),"") -> 34 | P35: =IF(COUNT(C35:F35,H35:J35)=0,"Missing",IF(COUNT(C35:F35,H35:J35)<COUNT($C$5:$F$5,$H$5:$J$5),"Incomplete","Graded")) -> Graded
A36: 30 | B36: =IFERROR(INDEX(Roster!$D$5:$D$56,MATCH($A36,Roster!$A$5:$A$56,0)),"(not on roster)") -> Alyssa Jasso | C36: 8 | D36: 8 | E36: 4 | F36: 4 | G36: =IF(COUNT(C36:F36)=0,"",SUM(C36:F36)) -> 24 | H36: 5 | I36: 5 | J36: 5 | K36: =IF(COUNT(H36:J36)=0,"",SUM(H36:J36)) -> 15 | L36: =IF(COUNT(C36:F36,H36:J36)=COUNT($C$5:$F$5,$H$5:$J$5),SUM(C36:F36,H36:J36),"") -> 39 | M36: =IF(ISNUMBER(L36),L36/$L$5,"") -> 0.78 | N36: =IF(ISNUMBER(L36),IF(L36>=$S$3,"Strong",IF(L36>=$S$4,"Satisfactory","Needs support")),"") -> Satisfactory | O36: =IF(ISNUMBER(L36),RANK(L36,$L$7:$L$58,0),"") -> 28 | P36: =IF(COUNT(C36:F36,H36:J36)=0,"Missing",IF(COUNT(C36:F36,H36:J36)<COUNT($C$5:$F$5,$H$5:$J$5),"Incomplete","Graded")) -> Graded
A37: 31 | B37: =IFERROR(INDEX(Roster!$D$5:$D$56,MATCH($A37,Roster!$A$5:$A$56,0)),"(not on roster)") -> Isabella Juarez | C37: 10 | D37: 15 | E37: 5 | F37: 5 | G37: =IF(COUNT(C37:F37)=0,"",SUM(C37:F37)) -> 35 | H37: 5 | I37: 5 | J37: 5 | K37: =IF(COUNT(H37:J37)=0,"",SUM(H37:J37)) -> 15 | L37: =IF(COUNT(C37:F37,H37:J37)=COUNT($C$5:$F$5,$H$5:$J$5),SUM(C37:F37,H37:J37),"") -> 50 | M37: =IF(ISNUMBER(L37),L37/$L$5,"") -> 1 | N37: =IF(ISNUMBER(L37),IF(L37>=$S$3,"Strong",IF(L37>=$S$4,"Satisfactory","Needs support")),"") -> Strong | O37: =IF(ISNUMBER(L37),RANK(L37,$L$7:$L$58,0),"") -> 1 | P37: =IF(COUNT(C37:F37,H37:J37)=0,"Missing",IF(COUNT(C37:F37,H37:J37)<COUNT($C$5:$F$5,$H$5:$J$5),"Incomplete","Graded")) -> Graded
A38: 32 | B38: =IFERROR(INDEX(Roster!$D$5:$D$56,MATCH($A38,Roster!$A$5:$A$56,0)),"(not on roster)") -> Maryam Ka | C38: 0 | D38: 10 | E38: 4 | F38: 4 | G38: =IF(COUNT(C38:F38)=0,"",SUM(C38:F38)) -> 18 | H38: 0 | I38: 5 | J38: 0 | K38: =IF(COUNT(H38:J38)=0,"",SUM(H38:J38)) -> 5 | L38: =IF(COUNT(C38:F38,H38:J38)=COUNT($C$5:$F$5,$H$5:$J$5),SUM(C38:F38,H38:J38),"") -> 23 | M38: =IF(ISNUMBER(L38),L38/$L$5,"") -> 0.46 | N38: =IF(ISNUMBER(L38),IF(L38>=$S$3,"Strong",IF(L38>=$S$4,"Satisfactory","Needs support")),"") -> Needs support | O38: =IF(ISNUMBER(L38),RANK(L38,$L$7:$L$58,0),"") -> 47 | P38: =IF(COUNT(C38:F38,H38:J38)=0,"Missing",IF(COUNT(C38:F38,H38:J38)<COUNT($C$5:$F$5,$H$5:$J$5),"Incomplete","Graded")) -> Graded
A39: 33 | B39: =IFERROR(INDEX(Roster!$D$5:$D$56,MATCH($A39,Roster!$A$5:$A$56,0)),"(not on roster)") -> Jenna Koestler | C39: 5 | D39: 12 | E39: 4 | F39: 4 | G39: =IF(COUNT(C39:F39)=0,"",SUM(C39:F39)) -> 25 | H39: 0 | I39: 5 | J39: 5 | K39: =IF(COUNT(H39:J39)=0,"",SUM(H39:J39)) -> 10 | L39: =IF(COUNT(C39:F39,H39:J39)=COUNT($C$5:$F$5,$H$5:$J$5),SUM(C39:F39,H39:J39),"") -> 35 | M39: =IF(ISNUMBER(L39),L39/$L$5,"") -> 0.7 | N39: =IF(ISNUMBER(L39),IF(L39>=$S$3,"Strong",IF(L39>=$S$4,"Satisfactory","Needs support")),"") -> Satisfactory | O39: =IF(ISNUMBER(L39),RANK(L39,$L$7:$L$58,0),"") -> 35 | P39: =IF(COUNT(C39:F39,H39:J39)=0,"Missing",IF(COUNT(C39:F39,H39:J39)<COUNT($C$5:$F$5,$H$5:$J$5),"Incomplete","Graded")) -> Graded
A40: 34 | B40: =IFERROR(INDEX(Roster!$D$5:$D$56,MATCH($A40,Roster!$A$5:$A$56,0)),"(not on roster)") -> Shawn Kwende | C40: 8 | D40: 15 | E40: 4 | F40: 4 | G40: =IF(COUNT(C40:F40)=0,"",SUM(C40:F40)) -> 31 | H40: 5 | I40: 5 | J40: 5 | K40: =IF(COUNT(H40:J40)=0,"",SUM(H40:J40)) -> 15 | L40: =IF(COUNT(C40:F40,H40:J40)=COUNT($C$5:$F$5,$H$5:$J$5),SUM(C40:F40,H40:J40),"") -> 46 | M40: =IF(ISNUMBER(L40),L40/$L$5,"") -> 0.92 | N40: =IF(ISNUMBER(L40),IF(L40>=$S$3,"Strong",IF(L40>=$S$4,"Satisfactory","Needs support")),"") -> Strong | O40: =IF(ISNUMBER(L40),RANK(L40,$L$7:$L$58,0),"") -> 8 | P40: =IF(COUNT(C40:F40,H40:J40)=0,"Missing",IF(COUNT(C40:F40,H40:J40)<COUNT($C$5:$F$5,$H$5:$J$5),"Incomplete","Graded")) -> Graded
...

Sheet Performance per Problem
A1: Performance per Problem
A2: All statistics are formulas that read the Quiz 1 Grades sheet (students with no scores are excluded). Use the Flag column to decide what to review in class.
A4: Question | B4: Max Pts | C4: # Graded | D4: Average | E4: Average % | F4: Median | G4: Std Dev | H4: Lowest | I4: Highest | J4: # Full Marks | K4: % Full Marks | L4: # Zeros | M4: % Zeros | N4: Flag | P4: Flag thresholds
A5: ='Quiz 1 Grades'!C6 -> 1.1 | B5: ='Quiz 1 Grades'!C$5 -> 10 | C5: =COUNT('Quiz 1 Grades'!C$7:C$58) -> 50 | D5: =IFERROR(AVERAGE('Quiz 1 Grades'!C$7:C$58),"") -> 6.32 | E5: =IFERROR(D5/B5,"") -> 0.632 | F5: =IFERROR(MEDIAN('Quiz 1 Grades'!C$7:C$58),"") -> 8 | G5: =IFERROR(STDEV('Quiz 1 Grades'!C$7:C$58),"") -> 3.145713 | H5: =IFERROR(MIN('Quiz 1 Grades'!C$7:C$58),"") -> 0 | I5: =IFERROR(MAX('Quiz 1 Grades'!C$7:C$58),"") -> 10 | J5: =COUNTIF('Quiz 1 Grades'!C$7:C$58,B5) -> 11 | K5: =IFERROR(J5/C5,"") -> 0.22 | L5: =COUNTIF('Quiz 1 Grades'!C$7:C$58,0) -> 4 | M5: =IFERROR(L5/C5,"") -> 0.08 | N5: =IF(ISNUMBER(E5),IF(OR(E5<$Q$6,AND(ISNUMBER(M5),M5>=$Q$7)),"Review in class",IF(E5<$Q$5,"Monitor","OK")),"") -> Monitor | P5: OK if average % ≥ | Q5: 0.75
A6: ='Quiz 1 Grades'!D6 -> 1.2 | B6: ='Quiz 1 Grades'!D$5 -> 15 | C6: =COUNT('Quiz 1 Grades'!D$7:D$58) -> 50 | D6: =IFERROR(AVERAGE('Quiz 1 Grades'!D$7:D$58),"") -> 11.92 | E6: =IFERROR(D6/B6,"") -> 0.79466667 | F6: =IFERROR(MEDIAN('Quiz 1 Grades'!D$7:D$58),"") -> 14 | G6: =IFERROR(STDEV('Quiz 1 Grades'!D$7:D$58),"") -> 3.5157953 | H6: =IFERROR(MIN('Quiz 1 Grades'!D$7:D$58),"") -> 5 | I6: =IFERROR(MAX('Quiz 1 Grades'!D$7:D$58),"") -> 15 | J6: =COUNTIF('Quiz 1 Grades'!D$7:D$58,B6) -> 25 | K6: =IFERROR(J6/C6,"") -> 0.5 | L6: =COUNTIF('Quiz 1 Grades'!D$7:D$58,0) -> 0 | M6: =IFERROR(L6/C6,"") -> 0 | N6: =IF(ISNUMBER(E6),IF(OR(E6<$Q$6,AND(ISNUMBER(M6),M6>=$Q$7)),"Review in class",IF(E6<$Q$5,"Monitor","OK")),"") -> OK | P6: Review in class if average % < | Q6: 0.6
A7: ='Quiz 1 Grades'!E6 -> 1.3 A | B7: ='Quiz 1 Grades'!E$5 -> 5 | C7: =COUNT('Quiz 1 Grades'!E$7:E$58) -> 50 | D7: =IFERROR(AVERAGE('Quiz 1 Grades'!E$7:E$58),"") -> 4.14 | E7: =IFERROR(D7/B7,"") -> 0.828 | F7: =IFERROR(MEDIAN('Quiz 1 Grades'!E$7:E$58),"") -> 4 | G7: =IFERROR(STDEV('Quiz 1 Grades'!E$7:E$58),"") -> 0.88086229 | H7: =IFERROR(MIN('Quiz 1 Grades'!E$7:E$58),"") -> 1 | I7: =IFERROR(MAX('Quiz 1 Grades'!E$7:E$58),"") -> 5 | J7: =COUNTIF('Quiz 1 Grades'!E$7:E$58,B7) -> 19 | K7: =IFERROR(J7/C7,"") -> 0.38 | L7: =COUNTIF('Quiz 1 Grades'!E$7:E$58,0) -> 0 | M7: =IFERROR(L7/C7,"") -> 0 | N7: =IF(ISNUMBER(E7),IF(OR(E7<$Q$6,AND(ISNUMBER(M7),M7>=$Q$7)),"Review in class",IF(E7<$Q$5,"Monitor","OK")),"") -> OK | P7: …or if % of zeros ≥ | Q7: 0.25
A8: ='Quiz 1 Grades'!F6 -> 1.3 B | B8: ='Quiz 1 Grades'!F$5 -> 5 | C8: =COUNT('Quiz 1 Grades'!F$7:F$58) -> 50 | D8: =IFERROR(AVERAGE('Quiz 1 Grades'!F$7:F$58),"") -> 4.08 | E8: =IFERROR(D8/B8,"") -> 0.816 | F8: =IFERROR(MEDIAN('Quiz 1 Grades'!F$7:F$58),"") -> 4 | G8: =IFERROR(STDEV('Quiz 1 Grades'!F$7:F$58),"") -> 0.80407127 | H8: =IFERROR(MIN('Quiz 1 Grades'!F$7:F$58),"") -> 2 | I8: =IFERROR(MAX('Quiz 1 Grades'!F$7:F$58),"") -> 5 | J8: =COUNTIF('Quiz 1 Grades'!F$7:F$58,B8) -> 16 | K8: =IFERROR(J8/C8,"") -> 0.32 | L8: =COUNTIF('Quiz 1 Grades'!F$7:F$58,0) -> 0 | M8: =IFERROR(L8/C8,"") -> 0 | N8: =IF(ISNUMBER(E8),IF(OR(E8<$Q$6,AND(ISNUMBER(M8),M8>=$Q$7)),"Review in class",IF(E8<$Q$5,"Monitor","OK")),"") -> OK | P8: (otherwise, below the OK line = Monitor)
A9: ='Quiz 1 Grades'!H6 -> 2.1 | B9: ='Quiz 1 Grades'!H$5 -> 5 | C9: =COUNT('Quiz 1 Grades'!H$7:H$58) -> 50 | D9: =IFERROR(AVERAGE('Quiz 1 Grades'!H$7:H$58),"") -> 4.1 | E9: =IFERROR(D9/B9,"") -> 0.82 | F9: =IFERROR(MEDIAN('Quiz 1 Grades'!H$7:H$58),"") -> 5 | G9: =IFERROR(STDEV('Quiz 1 Grades'!H$7:H$58),"") -> 1.9404397 | H9: =IFERROR(MIN('Quiz 1 Grades'!H$7:H$58),"") -> 0 | I9: =IFERROR(MAX('Quiz 1 Grades'!H$7:H$58),"") -> 5 | J9: =COUNTIF('Quiz 1 Grades'!H$7:H$58,B9) -> 41 | K9: =IFERROR(J9/C9,"") -> 0.82 | L9: =COUNTIF('Quiz 1 Grades'!H$7:H$58,0) -> 9 | M9: =IFERROR(L9/C9,"") -> 0.18 | N9: =IF(ISNUMBER(E9),IF(OR(E9<$Q$6,AND(ISNUMBER(M9),M9>=$Q$7)),"Review in class",IF(E9<$Q$5,"Monitor","OK")),"") -> OK
A10: ='Quiz 1 Grades'!I6 -> 2.2 | B10: ='Quiz 1 Grades'!I$5 -> 5 | C10: =COUNT('Quiz 1 Grades'!I$7:I$58) -> 50 | D10: =IFERROR(AVERAGE('Quiz 1 Grades'!I$7:I$58),"") -> 3.2 | E10: =IFERROR(D10/B10,"") -> 0.64 | F10: =IFERROR(MEDIAN('Quiz 1 Grades'!I$7:I$58),"") -> 5 | G10: =IFERROR(STDEV('Quiz 1 Grades'!I$7:I$58),"") -> 2.4243661 | H10: =IFERROR(MIN('Quiz 1 Grades'!I$7:I$58),"") -> 0 | I10: =IFERROR(MAX('Quiz 1 Grades'!I$7:I$58),"") -> 5 | J10: =COUNTIF('Quiz 1 Grades'!I$7:I$58,B10) -> 32 | K10: =IFERROR(J10/C10,"") -> 0.64 | L10: =COUNTIF('Quiz 1 Grades'!I$7:I$58,0) -> 18 | M10: =IFERROR(L10/C10,"") -> 0.36 | N10: =IF(ISNUMBER(E10),IF(OR(E10<$Q$6,AND(ISNUMBER(M10),M10>=$Q$7)),"Review in class",IF(E10<$Q$5,"Monitor","OK")),"") -> Review in class
