Workbook

Sheet Read Me
A1: Student Roster & Quiz 2 Grades
A2: Engineering Design · Fall 2026 · Teaching Assistant gradebook for Quiz 2 — same roster, tabs and layout as the Quiz 1 workbook; questions, points and answers come from the Quiz 2 answer key (quizz 2 v2 – Sol VF).
A4: Tabs in this workbook
A5: Roster | B5: Master list of the 52 students (last / first name). Type each student's Group # (column E). Quiz 2 score is pulled in automatically.
A6: Groups | B6: One row per project group (up to 13): choose the project track, see group size, size check and group Quiz 2 average; class split totals below.
A7: Answer Key | B7: Correct answer and points for every part of Quiz 2 (copied from the key), grading notes, the objective-tree weights and a check of the Pugh-chart totals.
A8: Quiz 2 Grades | B8: Score per part (1.1, 1.2 a, 1.2 b, 1.2 c, 1.3, 2.1, 2.2, 2.3). Problem subtotals, total (/50), %, performance band, rank and status are formulas. Class averages at the bottom.
A9: Performance per Problem | B9: Statistics for every sub-question (average, % of max, median, std dev, full marks, zeros) + charts. The Flag column tells you what to review in class.
A10: Class Summary | B10: Class-level numbers: graded / missing, average, median, high / low, performance bands and score distribution chart.
A11: Statistical Analysis | B11: Gaussian (normal) analysis: descriptive statistics with a confidence interval, five normality tests (Shapiro–Wilk, Anderson–Darling, Jarque–Bera, skewness & kurtosis z), empirical ±σ rule, histogram vs. normal curve, Q–Q plot, question analysis (difficulty, discrimination, Cronbach's α) and each student's z-score. Key findings at the top are written by formulas.
A13: Color legend
A14: Blue text, pale-yellow cell | B14: A value you type (scores, max points, group #, tracks, thresholds).
A15: Black text | B15: A formula — do not type over it; it updates automatically.
A16: Yellow row (Quiz 2 Grades) | B16: Student has no Quiz 2 scores yet (status = Missing).
A17: Green / yellow / red total | B17: Performance band: Strong / Satisfactory / Needs support (thresholds editable on Quiz 2 Grades, cells T3:T4).
A18: Red number | B18: A score of 0 on that part.
A20: How to…
A21: Enter a missing score | B21: Go to Quiz 2 Grades and type the points in the blue cells of that student's row. Everything else recalculates.
A22: Partly graded quiz | B22: If some sub-scores are still blank, the Status shows 'Incomplete' and the student is left out of the total, rank and class statistics until every sub-score is entered.
A23: Add a student | B23: Insert a new row INSIDE the tables (above the last student) on both Roster and Quiz 2 Grades, then copy the formulas down from the row above. All totals and statistics expand automatically.
A24: Form project groups | B24: Roster → pick a Group # for each student (column E, drop-down). Groups tab → choose the project track for each group. Sizes, tracks and averages update automatically.
A25: Change max points | B25: Quiz 2 Grades row 5 (blue cells, 'Max points'). Subtotals, %, statistics and score limits follow.
A26: Sort / filter | B26: Use the filter arrows on Quiz 2 Grades row 6 (e.g., sort by TOTAL, filter Performance = 'Needs support'). The max-points row and thresholds stay put; names follow the # automatically.
A28: Notes & assumptions
A29: Max points | B29: 1.1 = 15, 1.2 a = 6, 1.2 b = 1, 1.2 c = 3, 1.3 = 10 (Problem 1 = 35) and 2.1 = 2.2 = 2.3 = 5 (Problem 2 = 15), total 50 — all from the Quiz 2 answer key. The key gives 1.1 as one 15-point part, so it is one score here (a suggested split is on the Answer Key tab).
A30: Check in the key | B30: 1.2 a: the key gives the automatic arm cuff a weighted total of 2, but the key's own Pugh chart ("+" for data connectivity) adds up to 4. The 1.2 b answer is the same either way. Confirm with the instructor which total to accept (see the Answer Key tab).
A31: Performance bands | B31: Same as Quiz 1 (Quiz 2 is also out of 50): 40–50 green, 26–39 yellow, 0–25 red.
A32: Names | B32: Trailing spaces were removed and names split into Last / First (last word = last name). Please double-check spellings against Canvas (e.g., 'Jermy Brown').
A33: Starting point | B33: All 52 students start as 'Missing'. Scores, totals and statistics fill in as you grade (the normality tests need at least 12 fully graded quizzes).

Sheet Roster
A1: Class Roster
A2: Pick a Group # for each student (blue drop-down). Set each group's project track on the Groups tab → the student's track fills in automatically.
A4: # | B4: Last Name | C4: First Name | D4: Full Name | E4: Group # | F4: Project Track | G4: Quiz 2 (/50) | H4: Quiz 2 %
A5: 1 | B5: Abagwe | C5: David | D5: =TRIM(C5&" "&B5) -> David Abagwe | F5: =IF(E5="","Unassigned",IFERROR(IF(INDEX(Groups!$B$5:$B$17,MATCH(E5,Groups!$A$5:$A$17,0))="","Track not set",INDEX(Groups!$B$5:$B$17,MATCH(E5,Groups!$A$5:$A$17,0))),"Group not in table")) -> Unassigned | G5: =IFERROR(IF(INDEX('Quiz 2 Grades'!$Q$7:$Q$58,MATCH($A5,'Quiz 2 Grades'!$A$7:$A$58,0))="Graded",INDEX('Quiz 2 Grades'!$M$7:$M$58,MATCH($A5,'Quiz 2 Grades'!$A$7:$A$58,0)),INDEX('Quiz 2 Grades'!$Q$7:$Q$58,MATCH($A5,'Quiz 2 Grades'!$A$7:$A$58,0))),"") -> Missing | H5: =IF(ISNUMBER(G5),G5/'Quiz 2 Grades'!$M$5,"")
A6: 2 | B6: Acharya | C6: Sonu | D6: =TRIM(C6&" "&B6) -> Sonu Acharya | F6: =IF(E6="","Unassigned",IFERROR(IF(INDEX(Groups!$B$5:$B$17,MATCH(E6,Groups!$A$5:$A$17,0))="","Track not set",INDEX(Groups!$B$5:$B$17,MATCH(E6,Groups!$A$5:$A$17,0))),"Group not in table")) -> Unassigned | G6: =IFERROR(IF(INDEX('Quiz 2 Grades'!$Q$7:$Q$58,MATCH($A6,'Quiz 2 Grades'!$A$7:$A$58,0))="Graded",INDEX('Quiz 2 Grades'!$M$7:$M$58,MATCH($A6,'Quiz 2 Grades'!$A$7:$A$58,0)),INDEX('Quiz 2 Grades'!$Q$7:$Q$58,MATCH($A6,'Quiz 2 Grades'!$A$7:$A$58,0))),"") -> Missing | H6: =IF(ISNUMBER(G6),G6/'Quiz 2 Grades'!$M$5,"")
A7: 3 | B7: Adams | C7: Ashton | D7: =TRIM(C7&" "&B7) -> Ashton Adams | F7: =IF(E7="","Unassigned",IFERROR(IF(INDEX(Groups!$B$5:$B$17,MATCH(E7,Groups!$A$5:$A$17,0))="","Track not set",INDEX(Groups!$B$5:$B$17,MATCH(E7,Groups!$A$5:$A$17,0))),"Group not in table")) -> Unassigned | G7: =IFERROR(IF(INDEX('Quiz 2 Grades'!$Q$7:$Q$58,MATCH($A7,'Quiz 2 Grades'!$A$7:$A$58,0))="Graded",INDEX('Quiz 2 Grades'!$M$7:$M$58,MATCH($A7,'Quiz 2 Grades'!$A$7:$A$58,0)),INDEX('Quiz 2 Grades'!$Q$7:$Q$58,MATCH($A7,'Quiz 2 Grades'!$A$7:$A$58,0))),"") -> Missing | H7: =IF(ISNUMBER(G7),G7/'Quiz 2 Grades'!$M$5,"")
A8: 4 | B8: Albert | C8: Hayden | D8: =TRIM(C8&" "&B8) -> Hayden Albert | F8: =IF(E8="","Unassigned",IFERROR(IF(INDEX(Groups!$B$5:$B$17,MATCH(E8,Groups!$A$5:$A$17,0))="","Track not set",INDEX(Groups!$B$5:$B$17,MATCH(E8,Groups!$A$5:$A$17,0))),"Group not in table")) -> Unassigned | G8: =IFERROR(IF(INDEX('Quiz 2 Grades'!$Q$7:$Q$58,MATCH($A8,'Quiz 2 Grades'!$A$7:$A$58,0))="Graded",INDEX('Quiz 2 Grades'!$M$7:$M$58,MATCH($A8,'Quiz 2 Grades'!$A$7:$A$58,0)),INDEX('Quiz 2 Grades'!$Q$7:$Q$58,MATCH($A8,'Quiz 2 Grades'!$A$7:$A$58,0))),"") -> Missing | H8: =IF(ISNUMBER(G8),G8/'Quiz 2 Grades'!$M$5,"")
A9: 5 | B9: Allen | C9: Lani | D9: =TRIM(C9&" "&B9) -> Lani Allen | F9: =IF(E9="","Unassigned",IFERROR(IF(INDEX(Groups!$B$5:$B$17,MATCH(E9,Groups!$A$5:$A$17,0))="","Track not set",INDEX(Groups!$B$5:$B$17,MATCH(E9,Groups!$A$5:$A$17,0))),"Group not in table")) -> Unassigned | G9: =IFERROR(IF(INDEX('Quiz 2 Grades'!$Q$7:$Q$58,MATCH($A9,'Quiz 2 Grades'!$A$7:$A$58,0))="Graded",INDEX('Quiz 2 Grades'!$M$7:$M$58,MATCH($A9,'Quiz 2 Grades'!$A$7:$A$58,0)),INDEX('Quiz 2 Grades'!$Q$7:$Q$58,MATCH($A9,'Quiz 2 Grades'!$A$7:$A$58,0))),"") -> Missing | H9: =IF(ISNUMBER(G9),G9/'Quiz 2 Grades'!$M$5,"")
A10: 6 | B10: Andrade | C10: John David | D10: =TRIM(C10&" "&B10) -> John David Andrade | F10: =IF(E10="","Unassigned",IFERROR(IF(INDEX(Groups!$B$5:$B$17,MATCH(E10,Groups!$A$5:$A$17,0))="","Track not set",INDEX(Groups!$B$5:$B$17,MATCH(E10,Groups!$A$5:$A$17,0))),"Group not in table")) -> Unassigned | G10: =IFERROR(IF(INDEX('Quiz 2 Grades'!$Q$7:$Q$58,MATCH($A10,'Quiz 2 Grades'!$A$7:$A$58,0))="Graded",INDEX('Quiz 2 Grades'!$M$7:$M$58,MATCH($A10,'Quiz 2 Grades'!$A$7:$A$58,0)),INDEX('Quiz 2 Grades'!$Q$7:$Q$58,MATCH($A10,'Quiz 2 Grades'!$A$7:$A$58,0))),"") -> Missing | H10: =IF(ISNUMBER(G10),G10/'Quiz 2 Grades'!$M$5,"")
A11: 7 | B11: Atkins | C11: Landon | D11: =TRIM(C11&" "&B11) -> Landon Atkins | F11: =IF(E11="","Unassigned",IFERROR(IF(INDEX(Groups!$B$5:$B$17,MATCH(E11,Groups!$A$5:$A$17,0))="","Track not set",INDEX(Groups!$B$5:$B$17,MATCH(E11,Groups!$A$5:$A$17,0))),"Group not in table")) -> Unassigned | G11: =IFERROR(IF(INDEX('Quiz 2 Grades'!$Q$7:$Q$58,MATCH($A11,'Quiz 2 Grades'!$A$7:$A$58,0))="Graded",INDEX('Quiz 2 Grades'!$M$7:$M$58,MATCH($A11,'Quiz 2 Grades'!$A$7:$A$58,0)),INDEX('Quiz 2 Grades'!$Q$7:$Q$58,MATCH($A11,'Quiz 2 Grades'!$A$7:$A$58,0))),"") -> Missing | H11: =IF(ISNUMBER(G11),G11/'Quiz 2 Grades'!$M$5,"")
A12: 8 | B12: Borkland | C12: Ryan | D12: =TRIM(C12&" "&B12) -> Ryan Borkland | F12: =IF(E12="","Unassigned",IFERROR(IF(INDEX(Groups!$B$5:$B$17,MATCH(E12,Groups!$A$5:$A$17,0))="","Track not set",INDEX(Groups!$B$5:$B$17,MATCH(E12,Groups!$A$5:$A$17,0))),"Group not in table")) -> Unassigned | G12: =IFERROR(IF(INDEX('Quiz 2 Grades'!$Q$7:$Q$58,MATCH($A12,'Quiz 2 Grades'!$A$7:$A$58,0))="Graded",INDEX('Quiz 2 Grades'!$M$7:$M$58,MATCH($A12,'Quiz 2 Grades'!$A$7:$A$58,0)),INDEX('Quiz 2 Grades'!$Q$7:$Q$58,MATCH($A12,'Quiz 2 Grades'!$A$7:$A$58,0))),"") -> Missing | H12: =IF(ISNUMBER(G12),G12/'Quiz 2 Grades'!$M$5,"")
A13: 9 | B13: Brown | C13: Jermy | D13: =TRIM(C13&" "&B13) -> Jermy Brown | F13: =IF(E13="","Unassigned",IFERROR(IF(INDEX(Groups!$B$5:$B$17,MATCH(E13,Groups!$A$5:$A$17,0))="","Track not set",INDEX(Groups!$B$5:$B$17,MATCH(E13,Groups!$A$5:$A$17,0))),"Group not in table")) -> Unassigned | G13: =IFERROR(IF(INDEX('Quiz 2 Grades'!$Q$7:$Q$58,MATCH($A13,'Quiz 2 Grades'!$A$7:$A$58,0))="Graded",INDEX('Quiz 2 Grades'!$M$7:$M$58,MATCH($A13,'Quiz 2 Grades'!$A$7:$A$58,0)),INDEX('Quiz 2 Grades'!$Q$7:$Q$58,MATCH($A13,'Quiz 2 Grades'!$A$7:$A$58,0))),"") -> Missing | H13: =IF(ISNUMBER(G13),G13/'Quiz 2 Grades'!$M$5,"")
A14: 10 | B14: Calderon | C14: Eric | D14: =TRIM(C14&" "&B14) -> Eric Calderon | F14: =IF(E14="","Unassigned",IFERROR(IF(INDEX(Groups!$B$5:$B$17,MATCH(E14,Groups!$A$5:$A$17,0))="","Track not set",INDEX(Groups!$B$5:$B$17,MATCH(E14,Groups!$A$5:$A$17,0))),"Group not in table")) -> Unassigned | G14: =IFERROR(IF(INDEX('Quiz 2 Grades'!$Q$7:$Q$58,MATCH($A14,'Quiz 2 Grades'!$A$7:$A$58,0))="Graded",INDEX('Quiz 2 Grades'!$M$7:$M$58,MATCH($A14,'Quiz 2 Grades'!$A$7:$A$58,0)),INDEX('Quiz 2 Grades'!$Q$7:$Q$58,MATCH($A14,'Quiz 2 Grades'!$A$7:$A$58,0))),"") -> Missing | H14: =IF(ISNUMBER(G14),G14/'Quiz 2 Grades'!$M$5,"")
A15: 11 | B15: Camarillo | C15: Angel | D15: =TRIM(C15&" "&B15) -> Angel Camarillo | F15: =IF(E15="","Unassigned",IFERROR(IF(INDEX(Groups!$B$5:$B$17,MATCH(E15,Groups!$A$5:$A$17,0))="","Track not set",INDEX(Groups!$B$5:$B$17,MATCH(E15,Groups!$A$5:$A$17,0))),"Group not in table")) -> Unassigned | G15: =IFERROR(IF(INDEX('Quiz 2 Grades'!$Q$7:$Q$58,MATCH($A15,'Quiz 2 Grades'!$A$7:$A$58,0))="Graded",INDEX('Quiz 2 Grades'!$M$7:$M$58,MATCH($A15,'Quiz 2 Grades'!$A$7:$A$58,0)),INDEX('Quiz 2 Grades'!$Q$7:$Q$58,MATCH($A15,'Quiz 2 Grades'!$A$7:$A$58,0))),"") -> Missing | H15: =IF(ISNUMBER(G15),G15/'Quiz 2 Grades'!$M$5,"")
A16: 12 | B16: Cappel | C16: Gavin | D16: =TRIM(C16&" "&B16) -> Gavin Cappel | F16: =IF(E16="","Unassigned",IFERROR(IF(INDEX(Groups!$B$5:$B$17,MATCH(E16,Groups!$A$5:$A$17,0))="","Track not set",INDEX(Groups!$B$5:$B$17,MATCH(E16,Groups!$A$5:$A$17,0))),"Group not in table")) -> Unassigned | G16: =IFERROR(IF(INDEX('Quiz 2 Grades'!$Q$7:$Q$58,MATCH($A16,'Quiz 2 Grades'!$A$7:$A$58,0))="Graded",INDEX('Quiz 2 Grades'!$M$7:$M$58,MATCH($A16,'Quiz 2 Grades'!$A$7:$A$58,0)),INDEX('Quiz 2 Grades'!$Q$7:$Q$58,MATCH($A16,'Quiz 2 Grades'!$A$7:$A$58,0))),"") -> Missing | H16: =IF(ISNUMBER(G16),G16/'Quiz 2 Grades'!$M$5,"")
... A56: 52 | B56: Wildman | C56: Shaman | D56: =TRIM(C56&" "&B56) -> Shaman Wildman | F56: =IF(E56="","Unassigned",IFERROR(IF(INDEX(Groups!$B$5:$B$17,MATCH(E56,Groups!$A$5:$A$17,0))="","Track not set",INDEX(Groups!$B$5:$B$17,MATCH(E56,Groups!$A$5:$A$17,0))),"Group not in table")) -> Unassigned | G56: =IFERROR(IF(INDEX('Quiz 2 Grades'!$Q$7:$Q$58,MATCH($A56,'Quiz 2 Grades'!$A$7:$A$58,0))="Graded",INDEX('Quiz 2 Grades'!$M$7:$M$58,MATCH($A56,'Quiz 2 Grades'!$A$7:$A$58,0)),INDEX('Quiz 2 Grades'!$Q$7:$Q$58,MATCH($A56,'Quiz 2 Grades'!$A$7:$A$58,0))),"") -> Missing | H56: =IF(ISNUMBER(G56),G56/'Quiz 2 Grades'!$M$5,"")

Sheet Groups
A1: Project Groups
A2: Choose each group's project track (blue). Students are assigned on the Roster tab (column E). Group size, size check and averages are formulas.
A4: Group # | B4: Project Track (choose) | C4: # Students | D4: Size check | E4: Avg Quiz 2 %
A5: 1 | C5: =COUNTIF(Roster!$E$5:$E$56,A5) -> 0 | D5: =IF(C5=0,"",IF(OR(C5<$C$26,C5>$C$27),"Check size","OK")) | E5: =IFERROR(AVERAGEIF(Roster!$E$5:$E$56,A5,Roster!$H$5:$H$56),"")
A6: 2 | C6: =COUNTIF(Roster!$E$5:$E$56,A6) -> 0 | D6: =IF(C6=0,"",IF(OR(C6<$C$26,C6>$C$27),"Check size","OK")) | E6: =IFERROR(AVERAGEIF(Roster!$E$5:$E$56,A6,Roster!$H$5:$H$56),"")
A7: 3 | C7: =COUNTIF(Roster!$E$5:$E$56,A7) -> 0 | D7: =IF(C7=0,"",IF(OR(C7<$C$26,C7>$C$27),"Check size","OK")) | E7: =IFERROR(AVERAGEIF(Roster!$E$5:$E$56,A7,Roster!$H$5:$H$56),"")
A8: 4 | C8: =COUNTIF(Roster!$E$5:$E$56,A8) -> 0 | D8: =IF(C8=0,"",IF(OR(C8<$C$26,C8>$C$27),"Check size","OK")) | E8: =IFERROR(AVERAGEIF(Roster!$E$5:$E$56,A8,Roster!$H$5:$H$56),"")
A9: 5 | C9: =COUNTIF(Roster!$E$5:$E$56,A9) -> 0 | D9: =IF(C9=0,"",IF(OR(C9<$C$26,C9>$C$27),"Check size","OK")) | E9: =IFERROR(AVERAGEIF(Roster!$E$5:$E$56,A9,Roster!$H$5:$H$56),"")
A10: 6 | C10: =COUNTIF(Roster!$E$5:$E$56,A10) -> 0 | D10: =IF(C10=0,"",IF(OR(C10<$C$26,C10>$C$27),"Check size","OK")) | E10: =IFERROR(AVERAGEIF(Roster!$E$5:$E$56,A10,Roster!$H$5:$H$56),"")
A11: 7 | C11: =COUNTIF(Roster!$E$5:$E$56,A11) -> 0 | D11: =IF(C11=0,"",IF(OR(C11<$C$26,C11>$C$27),"Check size","OK")) | E11: =IFERROR(AVERAGEIF(Roster!$E$5:$E$56,A11,Roster!$H$5:$H$56),"")
A12: 8 | C12: =COUNTIF(Roster!$E$5:$E$56,A12) -> 0 | D12: =IF(C12=0,"",IF(OR(C12<$C$26,C12>$C$27),"Check size","OK")) | E12: =IFERROR(AVERAGEIF(Roster!$E$5:$E$56,A12,Roster!$H$5:$H$56),"")
A13: 9 | C13: =COUNTIF(Roster!$E$5:$E$56,A13) -> 0 | D13: =IF(C13=0,"",IF(OR(C13<$C$26,C13>$C$27),"Check size","OK")) | E13: =IFERROR(AVERAGEIF(Roster!$E$5:$E$56,A13,Roster!$H$5:$H$56),"")
A14: 10 | C14: =COUNTIF(Roster!$E$5:$E$56,A14) -> 0 | D14: =IF(C14=0,"",IF(OR(C14<$C$26,C14>$C$27),"Check size","OK")) | E14: =IFERROR(AVERAGEIF(Roster!$E$5:$E$56,A14,Roster!$H$5:$H$56),"")
A15: 11 | C15: =COUNTIF(Roster!$E$5:$E$56,A15) -> 0 | D15: =IF(C15=0,"",IF(OR(C15<$C$26,C15>$C$27),"Check size","OK")) | E15: =IFERROR(AVERAGEIF(Roster!$E$5:$E$56,A15,Roster!$H$5:$H$56),"")
A16: 12 | C16: =COUNTIF(Roster!$E$5:$E$56,A16) -> 0 | D16: =IF(C16=0,"",IF(OR(C16<$C$26,C16>$C$27),"Check size","OK")) | E16: =IFERROR(AVERAGEIF(Roster!$E$5:$E$56,A16,Roster!$H$5:$H$56),"")
A17: 13 | C17: =COUNTIF(Roster!$E$5:$E$56,A17) -> 0 | D17: =IF(C17=0,"",IF(OR(C17<$C$26,C17>$C$27),"Check size","OK")) | E17: =IFERROR(AVERAGEIF(Roster!$E$5:$E$56,A17,Roster!$H$5:$H$56),"")
A19: Class split & group sizing
A20: Students on roster | C20: =COUNTA(Roster!$B$5:$B$56) -> 52
A21: Assigned to a group | C21: =COUNT(Roster!$E$5:$E$56) -> 0
A22: Not yet assigned | C22: =COUNTBLANK(Roster!$E$5:$E$56) -> 52
A23: Methylene Blue Removal students | C23: =COUNTIF(Roster!$F$5:$F$56,"Methylene Blue Removal") -> 0
A24: Oxygenation students | C24: =COUNTIF(Roster!$F$5:$F$56,"Oxygenation") -> 0
A25: Groups on Methylene Blue Removal | C25: =COUNTIFS($B$5:$B$17,"Methylene Blue Removal",$C$5:$C$17,">0") -> 0
A26: Minimum students per group | C26: 4
A27: Maximum students per group | C27: 5
A28: Groups needed (at max size) | C28: =ROUNDUP(C20/C27,0) -> 11

Sheet Answer Key
A1: Quiz 2 — Answer Key & Grading Guide
A2: Answers are copied from the instructor's key (quizz 2 v2 – Sol VF). Points link to the Max points row of Quiz 2 Grades. Rows marked "Suggested" are grading ideas where the key gives no split; red cells = something to confirm with the instructor.
A4: Points at a glance
A5: Question | B5: What it asks | C5: Points | D5: Answer (from the key)
A6: 1.1 | B6: Weighted objective tree for Dr. Haack's device | C6: ='Quiz 2 Grades'!C5 -> 15 | D6: Local | global weights in the table under 1.1 below (leaf globals 0.15, 0.15, 0.4, 0.1, 0.06, 0.06, 0.08)
A7: 1.2 a | B7: Pugh chart: weighted total of each monitor (show work) | C7: ='Quiz 2 Grades'!D5 -> 6 | D7: Automatic arm cuff 2 · Wrist cuff 1 · Smartwatch −4 (the chart itself gives 4 for the arm cuff — see 1.2 a)
A8: 1.2 b | B8: Which monitor should the clinic choose? | C8: ='Quiz 2 Grades'!E5 -> 1 | D8: Automatic arm cuff
A9: 1.2 c | B9: Why does the smartwatch finish last? | C9: ='Quiz 2 Grades'!F5 -> 3 | D9: It scores poorly on the criteria with the highest weights — accuracy and cost
A10: 1.3 | B10: Water filter: change two criteria weights for one client | C10: ='Quiz 2 Grades'!G5 -> 10 | D10: Answers vary — one client, two new weights (1–5), each with a reasonable reason
A11: 2.1 | B11: Constraints: which statement is NOT true? | C11: ='Quiz 2 Grades'!I5 -> 5 | D11: c) Cannot be added to the objectives tree
A12: 2.2 | B12: Select the FALSE statement | C12: ='Quiz 2 Grades'!J5 -> 5 | D12: c) The engineering code of ethics encourages engineers to perform services in areas outside their competence
A13: 2.3 | B13: Team keeps explaining the data away (week-1 concept) | C13: ='Quiz 2 Grades'!K5 -> 5 | D13: b) Anchoring bias
A14: Problem 1 | B14: Objective tree, Pugh chart, water filter | C14: =SUM(C6:C10) -> 35 | D14: Key: 35 pts
A15: Problem 2 | B15: Multiple choice | C15: =SUM(C11:C13) -> 15 | D15: Key: 15 pts
A16: TOTAL | B16: Whole quiz | C16: =C14+C15 -> 50 | D16: =IF(AND(C14=35,C15=15),"✔ Matches the key (35 + 15 = 50)","✘ Differs from the key (35 + 15 = 50) — check row 5 of Quiz 2 Grades") -> ✔ Matches the key (35 + 15 = 50)
A18: Answers and how to grade each part
A19: ="1.1 Weighted objective tree — "&'Quiz 2 Grades'!C5&" pts" -> 1.1 Weighted objective tree — 15 pts
A20: Answer (key) | B20: Tree from the key (local weight | global weight): Dr. Haack device 1.0 | 1.0 → Efficient 0.3 | 0.3 (Detect elasticity 0.5 | 0.15, Detect viscosity 0.5 | 0.15) · Safe 0.5 | 0.5 (Avoid human exposure to samples 0.8 | 0.4, Avoid mechanical injuries 0.2 | 0.1) · Marketable 0.2 | 0.2 (Portable 0.3 | 0.06, Inexpensive 0.3 | 0.06, Fast 0.4 | 0.08).
A21: How to grade | B21: Suggested — the key gives 15 pts for the whole tree but no split: 1 pt for the three top-level weights (0.3 / 0.5 / 0.2), 1 pt for each of the 7 sub-objective local weights and 1 pt for each of the 7 global weights (global = parent's global × local) = 15. Quiz rule 4: if a local weight is wrong but the multiplication is right, still give the global-weight point.
A22: Level | B22: Objective | C22: Local weight (key) | D22: Global weight (key) | E22: Parent global × local | F22: Matches?
A23: 0 | B23: Dr. Haack device | C23: 1 | D23: 1 | E23: =C23 -> 1 | F23: =IF(ROUND(E23-D23,6)=0,"✔","✘ check") -> ✔
A24: 1 | B24: Efficient | C24: 0.3 | D24: 0.3 | E24: =D23*C24 -> 0.3 | F24: =IF(ROUND(E24-D24,6)=0,"✔","✘ check") -> ✔
A25: 2 | B25: Detect elasticity | C25: 0.5 | D25: 0.15 | E25: =D24*C25 -> 0.15 | F25: =IF(ROUND(E25-D25,6)=0,"✔","✘ check") -> ✔
A26: 2 | B26: Detect viscosity | C26: 0.5 | D26: 0.15 | E26: =D24*C26 -> 0.15 | F26: =IF(ROUND(E26-D26,6)=0,"✔","✘ check") -> ✔
A27: 1 | B27: Safe | C27: 0.5 | D27: 0.5 | E27: =D23*C27 -> 0.5 | F27: =IF(ROUND(E27-D27,6)=0,"✔","✘ check") -> ✔
A28: 2 | B28: Avoid human exposure to samples | C28: 0.8 | D28: 0.4 | E28: =D27*C28 -> 0.4 | F28: =IF(ROUND(E28-D28,6)=0,"✔","✘ check") -> ✔
A29: 2 | B29: Avoid mechanical injuries | C29: 0.2 | D29: 0.1 | E29: =D27*C29 -> 0.1 | F29: =IF(ROUND(E29-D29,6)=0,"✔","✘ check") -> ✔
A30: 1 | B30: Marketable | C30: 0.2 | D30: 0.2 | E30: =D23*C30 -> 0.2 | F30: =IF(ROUND(E30-D30,6)=0,"✔","✘ check") -> ✔
A31: 2 | B31: Portable | C31: 0.3 | D31: 0.06 | E31: =D30*C31 -> 0.06 | F31: =IF(ROUND(E31-D31,6)=0,"✔","✘ check") -> ✔
A32: 2 | B32: Inexpensive | C32: 0.3 | D32: 0.06 | E32: =D30*C32 -> 0.06 | F32: =IF(ROUND(E32-D32,6)=0,"✔","✘ check") -> ✔
A33: 2 | B33: Fast | C33: 0.4 | D33: 0.08 | E33: =D30*C33 -> 0.08 | F33: =IF(ROUND(E33-D33,6)=0,"✔","✘ check") -> ✔
B34: Sum of the 7 sub-objective global weights | D34: =D25+D26+D28+D29+D31+D32+D33 -> 1 | E34: =E25+E26+E28+E29+E31+E32+E33 -> 1 | F34: =IF(ROUND(D34-1,6)=0,"✔ = 1","✘ check") -> ✔ = 1
A36: ="1.2 Pugh chart, blood pressure monitor — a) "&'Quiz 2 Grades'!D5&" pts · b) "&'Quiz 2 Grades'!E5&" pt · c) "&'Quiz 2 Grades'!F5&" pts" -> 1.2 Pugh chart, blood pressure monitor — a) 6 pts · b) 1 pt · c) 3 pts
A37: 1.2 a key | B37: Automatic arm cuff: (0 x 5) + (2 x 3) + (-1 x 4) + (0 x 2) = 2 Wrist Cuff: (-1 x 5) + (2 x 3) + (-1 x 4) + (1 x 2) + (1 x 2) = 1 Smart watch: (-2 x 5) + (2 x 3) + (-2 x 4) + (2 x 2) + (2 x 2) = -4
A38: 1.2 a check | B38: The key's line for the automatic arm cuff uses 0 for data connectivity and leaves out portability, but its own chart gives the arm cuff "+" for data connectivity: (0×5) + (2×3) + (−1×4) + (1×2) + (0×2) = 4 (see the table below). Confirm with the instructor which total gets credit — suggestion: accept 2 or 4. The ranking and the 1.2 b answer do not change.
A39: 1.2 a grade | B39: Suggested: 2 pts per monitor — 1 for the work (each rating × its weight, summed over the five criteria) and 1 for the correct total.
A40: 1.2 b key | B40: Automatic arm cuff
A41: 1.2 b grade | B41: 1 pt. Suggested (quiz rule 4): also give it when the student picks the highest total from their own 1.2 a numbers.
A42: 1.2 c key | B42: It scores poorly in the categories that have a higher weight – accuracy and cost. Therefore, based on the most important criteria, it fails.
A43: 1.2 c grade | B43: Suggested: 3 pts for linking the smartwatch's low scores (– –) to the two highest-weighted criteria, accuracy (5) and cost (4); 2 pts if they name accuracy and cost but say nothing about the weights; 1 pt if they only say the weights matter without naming the criteria.
...

Sheet Quiz 2 Grades
A1: Quiz 2 — Grades by Student
A2: Blue cells = scores you type. Subtotals, total, %, band, rank and status are formulas. Rows turn yellow when a student has no scores. | S2: Performance bands
S3: Strong (green) if total ≥ | T3: 40
A4: Student | C4: ="Problem 1 ("&H5&" pts)" -> Problem 1 (35 pts) | I4: ="Problem 2 ("&L5&" pts)" -> Problem 2 (15 pts) | M4: Results | S4: Satisfactory (yellow) if total ≥ | T4: 26
B5: Max points | C5: 15 | D5: 6 | E5: 1 | F5: 3 | G5: 10 | H5: =SUM(C5:G5) -> 35 | I5: 5 | J5: 5 | K5: 5 | L5: =SUM(I5:K5) -> 15 | M5: =H5+L5 -> 50 | S5: Needs support (red) if total < | T5: =T4 -> 26
A6: # | B6: Student Name | C6: 1.1 | D6: 1.2 a | E6: 1.2 b | F6: 1.2 c | G6: 1.3 | H6: P1 Total | I6: 2.1 | J6: 2.2 | K6: 2.3 | L6: P2 Total | M6: TOTAL | N6: % | O6: Performance | P6: Rank | Q6: Status
A7: 1 | B7: =IFERROR(INDEX(Roster!$D$5:$D$56,MATCH($A7,Roster!$A$5:$A$56,0)),"(not on roster)") -> David Abagwe | H7: =IF(COUNT(C7:G7)=0,"",SUM(C7:G7)) | L7: =IF(COUNT(I7:K7)=0,"",SUM(I7:K7)) | M7: =IF(COUNT(C7:G7,I7:K7)=COUNT($C$5:$G$5,$I$5:$K$5),SUM(C7:G7,I7:K7),"") | N7: =IF(ISNUMBER(M7),M7/$M$5,"") | O7: =IF(ISNUMBER(M7),IF(M7>=$T$3,"Strong",IF(M7>=$T$4,"Satisfactory","Needs support")),"") | P7: =IF(ISNUMBER(M7),RANK(M7,$M$7:$M$58,0),"") | Q7: =IF(COUNT(C7:G7,I7:K7)=0,"Missing",IF(COUNT(C7:G7,I7:K7)<COUNT($C$5:$G$5,$I$5:$K$5),"Incomplete","Graded")) -> Missing
A8: 2 | B8: =IFERROR(INDEX(Roster!$D$5:$D$56,MATCH($A8,Roster!$A$5:$A$56,0)),"(not on roster)") -> Sonu Acharya | H8: =IF(COUNT(C8:G8)=0,"",SUM(C8:G8)) | L8: =IF(COUNT(I8:K8)=0,"",SUM(I8:K8)) | M8: =IF(COUNT(C8:G8,I8:K8)=COUNT($C$5:$G$5,$I$5:$K$5),SUM(C8:G8,I8:K8),"") | N8: =IF(ISNUMBER(M8),M8/$M$5,"") | O8: =IF(ISNUMBER(M8),IF(M8>=$T$3,"Strong",IF(M8>=$T$4,"Satisfactory","Needs support")),"") | P8: =IF(ISNUMBER(M8),RANK(M8,$M$7:$M$58,0),"") | Q8: =IF(COUNT(C8:G8,I8:K8)=0,"Missing",IF(COUNT(C8:G8,I8:K8)<COUNT($C$5:$G$5,$I$5:$K$5),"Incomplete","Graded")) -> Missing
A9: 3 | B9: =IFERROR(INDEX(Roster!$D$5:$D$56,MATCH($A9,Roster!$A$5:$A$56,0)),"(not on roster)") -> Ashton Adams | H9: =IF(COUNT(C9:G9)=0,"",SUM(C9:G9)) | L9: =IF(COUNT(I9:K9)=0,"",SUM(I9:K9)) | M9: =IF(COUNT(C9:G9,I9:K9)=COUNT($C$5:$G$5,$I$5:$K$5),SUM(C9:G9,I9:K9),"") | N9: =IF(ISNUMBER(M9),M9/$M$5,"") | O9: =IF(ISNUMBER(M9),IF(M9>=$T$3,"Strong",IF(M9>=$T$4,"Satisfactory","Needs support")),"") | P9: =IF(ISNUMBER(M9),RANK(M9,$M$7:$M$58,0),"") | Q9: =IF(COUNT(C9:G9,I9:K9)=0,"Missing",IF(COUNT(C9:G9,I9:K9)<COUNT($C$5:$G$5,$I$5:$K$5),"Incomplete","Graded")) -> Missing
A10: 4 | B10: =IFERROR(INDEX(Roster!$D$5:$D$56,MATCH($A10,Roster!$A$5:$A$56,0)),"(not on roster)") -> Hayden Albert | H10: =IF(COUNT(C10:G10)=0,"",SUM(C10:G10)) | L10: =IF(COUNT(I10:K10)=0,"",SUM(I10:K10)) | M10: =IF(COUNT(C10:G10,I10:K10)=COUNT($C$5:$G$5,$I$5:$K$5),SUM(C10:G10,I10:K10),"") | N10: =IF(ISNUMBER(M10),M10/$M$5,"") | O10: =IF(ISNUMBER(M10),IF(M10>=$T$3,"Strong",IF(M10>=$T$4,"Satisfactory","Needs support")),"") | P10: =IF(ISNUMBER(M10),RANK(M10,$M$7:$M$58,0),"") | Q10: =IF(COUNT(C10:G10,I10:K10)=0,"Missing",IF(COUNT(C10:G10,I10:K10)<COUNT($C$5:$G$5,$I$5:$K$5),"Incomplete","Graded")) -> Missing
A11: 5 | B11: =IFERROR(INDEX(Roster!$D$5:$D$56,MATCH($A11,Roster!$A$5:$A$56,0)),"(not on roster)") -> Lani Allen | H11: =IF(COUNT(C11:G11)=0,"",SUM(C11:G11)) | L11: =IF(COUNT(I11:K11)=0,"",SUM(I11:K11)) | M11: =IF(COUNT(C11:G11,I11:K11)=COUNT($C$5:$G$5,$I$5:$K$5),SUM(C11:G11,I11:K11),"") | N11: =IF(ISNUMBER(M11),M11/$M$5,"") | O11: =IF(ISNUMBER(M11),IF(M11>=$T$3,"Strong",IF(M11>=$T$4,"Satisfactory","Needs support")),"") | P11: =IF(ISNUMBER(M11),RANK(M11,$M$7:$M$58,0),"") | Q11: =IF(COUNT(C11:G11,I11:K11)=0,"Missing",IF(COUNT(C11:G11,I11:K11)<COUNT($C$5:$G$5,$I$5:$K$5),"Incomplete","Graded")) -> Missing
A12: 6 | B12: =IFERROR(INDEX(Roster!$D$5:$D$56,MATCH($A12,Roster!$A$5:$A$56,0)),"(not on roster)") -> John David Andrade | H12: =IF(COUNT(C12:G12)=0,"",SUM(C12:G12)) | L12: =IF(COUNT(I12:K12)=0,"",SUM(I12:K12)) | M12: =IF(COUNT(C12:G12,I12:K12)=COUNT($C$5:$G$5,$I$5:$K$5),SUM(C12:G12,I12:K12),"") | N12: =IF(ISNUMBER(M12),M12/$M$5,"") | O12: =IF(ISNUMBER(M12),IF(M12>=$T$3,"Strong",IF(M12>=$T$4,"Satisfactory","Needs support")),"") | P12: =IF(ISNUMBER(M12),RANK(M12,$M$7:$M$58,0),"") | Q12: =IF(COUNT(C12:G12,I12:K12)=0,"Missing",IF(COUNT(C12:G12,I12:K12)<COUNT($C$5:$G$5,$I$5:$K$5),"Incomplete","Graded")) -> Missing
A13: 7 | B13: =IFERROR(INDEX(Roster!$D$5:$D$56,MATCH($A13,Roster!$A$5:$A$56,0)),"(not on roster)") -> Landon Atkins | H13: =IF(COUNT(C13:G13)=0,"",SUM(C13:G13)) | L13: =IF(COUNT(I13:K13)=0,"",SUM(I13:K13)) | M13: =IF(COUNT(C13:G13,I13:K13)=COUNT($C$5:$G$5,$I$5:$K$5),SUM(C13:G13,I13:K13),"") | N13: =IF(ISNUMBER(M13),M13/$M$5,"") | O13: =IF(ISNUMBER(M13),IF(M13>=$T$3,"Strong",IF(M13>=$T$4,"Satisfactory","Needs support")),"") | P13: =IF(ISNUMBER(M13),RANK(M13,$M$7:$M$58,0),"") | Q13: =IF(COUNT(C13:G13,I13:K13)=0,"Missing",IF(COUNT(C13:G13,I13:K13)<COUNT($C$5:$G$5,$I$5:$K$5),"Incomplete","Graded")) -> Missing
A14: 8 | B14: =IFERROR(INDEX(Roster!$D$5:$D$56,MATCH($A14,Roster!$A$5:$A$56,0)),"(not on roster)") -> Ryan Borkland | H14: =IF(COUNT(C14:G14)=0,"",SUM(C14:G14)) | L14: =IF(COUNT(I14:K14)=0,"",SUM(I14:K14)) | M14: =IF(COUNT(C14:G14,I14:K14)=COUNT($C$5:$G$5,$I$5:$K$5),SUM(C14:G14,I14:K14),"") | N14: =IF(ISNUMBER(M14),M14/$M$5,"") | O14: =IF(ISNUMBER(M14),IF(M14>=$T$3,"Strong",IF(M14>=$T$4,"Satisfactory","Needs support")),"") | P14: =IF(ISNUMBER(M14),RANK(M14,$M$7:$M$58,0),"") | Q14: =IF(COUNT(C14:G14,I14:K14)=0,"Missing",IF(COUNT(C14:G14,I14:K14)<COUNT($C$5:$G$5,$I$5:$K$5),"Incomplete","Graded")) -> Missing
A15: 9 | B15: =IFERROR(INDEX(Roster!$D$5:$D$56,MATCH($A15,Roster!$A$5:$A$56,0)),"(not on roster)") -> Jermy Brown | H15: =IF(COUNT(C15:G15)=0,"",SUM(C15:G15)) | L15: =IF(COUNT(I15:K15)=0,"",SUM(I15:K15)) | M15: =IF(COUNT(C15:G15,I15:K15)=COUNT($C$5:$G$5,$I$5:$K$5),SUM(C15:G15,I15:K15),"") | N15: =IF(ISNUMBER(M15),M15/$M$5,"") | O15: =IF(ISNUMBER(M15),IF(M15>=$T$3,"Strong",IF(M15>=$T$4,"Satisfactory","Needs support")),"") | P15: =IF(ISNUMBER(M15),RANK(M15,$M$7:$M$58,0),"") | Q15: =IF(COUNT(C15:G15,I15:K15)=0,"Missing",IF(COUNT(C15:G15,I15:K15)<COUNT($C$5:$G$5,$I$5:$K$5),"Incomplete","Graded")) -> Missing
A16: 10 | B16: =IFERROR(INDEX(Roster!$D$5:$D$56,MATCH($A16,Roster!$A$5:$A$56,0)),"(not on roster)") -> Eric Calderon | H16: =IF(COUNT(C16:G16)=0,"",SUM(C16:G16)) | L16: =IF(COUNT(I16:K16)=0,"",SUM(I16:K16)) | M16: =IF(COUNT(C16:G16,I16:K16)=COUNT($C$5:$G$5,$I$5:$K$5),SUM(C16:G16,I16:K16),"") | N16: =IF(ISNUMBER(M16),M16/$M$5,"") | O16: =IF(ISNUMBER(M16),IF(M16>=$T$3,"Strong",IF(M16>=$T$4,"Satisfactory","Needs support")),"") | P16: =IF(ISNUMBER(M16),RANK(M16,$M$7:$M$58,0),"") | Q16: =IF(COUNT(C16:G16,I16:K16)=0,"Missing",IF(COUNT(C16:G16,I16:K16)<COUNT($C$5:$G$5,$I$5:$K$5),"Incomplete","Graded")) -> Missing
A17: 11 | B17: =IFERROR(INDEX(Roster!$D$5:$D$56,MATCH($A17,Roster!$A$5:$A$56,0)),"(not on roster)") -> Angel Camarillo | H17: =IF(COUNT(C17:G17)=0,"",SUM(C17:G17)) | L17: =IF(COUNT(I17:K17)=0,"",SUM(I17:K17)) | M17: =IF(COUNT(C17:G17,I17:K17)=COUNT($C$5:$G$5,$I$5:$K$5),SUM(C17:G17,I17:K17),"") | N17: =IF(ISNUMBER(M17),M17/$M$5,"") | O17: =IF(ISNUMBER(M17),IF(M17>=$T$3,"Strong",IF(M17>=$T$4,"Satisfactory","Needs support")),"") | P17: =IF(ISNUMBER(M17),RANK(M17,$M$7:$M$58,0),"") | Q17: =IF(COUNT(C17:G17,I17:K17)=0,"Missing",IF(COUNT(C17:G17,I17:K17)<COUNT($C$5:$G$5,$I$5:$K$5),"Incomplete","Graded")) -> Missing
A18: 12 | B18: =IFERROR(INDEX(Roster!$D$5:$D$56,MATCH($A18,Roster!$A$5:$A$56,0)),"(not on roster)") -> Gavin Cappel | H18: =IF(COUNT(C18:G18)=0,"",SUM(C18:G18)) | L18: =IF(COUNT(I18:K18)=0,"",SUM(I18:K18)) | M18: =IF(COUNT(C18:G18,I18:K18)=COUNT($C$5:$G$5,$I$5:$K$5),SUM(C18:G18,I18:K18),"") | N18: =IF(ISNUMBER(M18),M18/$M$5,"") | O18: =IF(ISNUMBER(M18),IF(M18>=$T$3,"Strong",IF(M18>=$T$4,"Satisfactory","Needs support")),"") | P18: =IF(ISNUMBER(M18),RANK(M18,$M$7:$M$58,0),"") | Q18: =IF(COUNT(C18:G18,I18:K18)=0,"Missing",IF(COUNT(C18:G18,I18:K18)<COUNT($C$5:$G$5,$I$5:$K$5),"Incomplete","Graded")) -> Missing
... A58: 52 | B58: =IFERROR(INDEX(Roster!$D$5:$D$56,MATCH($A58,Roster!$A$5:$A$56,0)),"(not on roster)") -> Shaman Wildman | H58: =IF(COUNT(C58:G58)=0,"",SUM(C58:G58)) | L58: =IF(COUNT(I58:K58)=0,"",SUM(I58:K58)) | M58: =IF(COUNT(C58:G58,I58:K58)=COUNT($C$5:$G$5,$I$5:$K$5),SUM(C58:G58,I58:K58),"") | N58: =IF(ISNUMBER(M58),M58/$M$5,"") | O58: =IF(ISNUMBER(M58),IF(M58>=$T$3,"Strong",IF(M58>=$T$4,"Satisfactory","Needs support")),"") | P58: =IF(ISNUMBER(M58),RANK(M58,$M$7:$M$58,0),"") | Q58: =IF(COUNT(C58:G58,I58:K58)=0,"Missing",IF(COUNT(C58:G58,I58:K58)<COUNT($C$5:$G$5,$I$5:$K$5),"Incomplete","Graded")) -> Missing
B60: Class average | C60: =IFERROR(AVERAGE(C7:C58),"") | D60: =IFERROR(AVERAGE(D7:D58),"") | E60: =IFERROR(AVERAGE(E7:E58),"") | F60: =IFERROR(AVERAGE(F7:F58),"") | G60: =IFERROR(AVERAGE(G7:G58),"") | H60: =IFERROR(AVERAGE(H7:H58),"") | I60: =IFERROR(AVERAGE(I7:I58),"") | J60: =IFERROR(AVERAGE(J7:J58),"") | ... N60: =IFERROR(AVERAGE(N7:N58),"")
B61: Average % of max | C61: =IFERROR(C60/C$5,"") | D61: =IFERROR(D60/D$5,"") | E61: =IFERROR(E60/E$5,"") | F61: =IFERROR(F60/F$5,"") | G61: =IFERROR(G60/G$5,"") | H61: =IFERROR(H60/H$5,"") | I61: =IFERROR(I60/I$5,"") | J61: =IFERROR(J60/J$5,"") | ... M61: =IFERROR(M60/M$5,"")
B62: Highest | C62: =IFERROR(MAX(C7:C58),"") -> 0 | D62: =IFERROR(MAX(D7:D58),"") -> 0 | E62: =IFERROR(MAX(E7:E58),"") -> 0 | F62: =IFERROR(MAX(F7:F58),"") -> 0 | G62: =IFERROR(MAX(G7:G58),"") -> 0 | H62: =IFERROR(MAX(H7:H58),"") -> 0 | I62: =IFERROR(MAX(I7:I58),"") -> 0 | J62: =IFERROR(MAX(J7:J58),"") -> 0 | ... N62: =IFERROR(MAX(N7:N58),"") -> 0
B63: Lowest | C63: =IFERROR(MIN(C7:C58),"") -> 0 | D63: =IFERROR(MIN(D7:D58),"") -> 0 | E63: =IFERROR(MIN(E7:E58),"") -> 0 | F63: =IFERROR(MIN(F7:F58),"") -> 0 | G63: =IFERROR(MIN(G7:G58),"") -> 0 | H63: =IFERROR(MIN(H7:H58),"") -> 0 | I63: =IFERROR(MIN(I7:I58),"") -> 0 | J63: =IFERROR(MIN(J7:J58),"") -> 0 | ... N63: =IFERROR(MIN(N7:N58),"") -> 0
B64: Students graded | C64: =IFERROR(COUNT(C7:C58),"") -> 0 | D64: =IFERROR(COUNT(D7:D58),"") -> 0 | E64: =IFERROR(COUNT(E7:E58),"") -> 0 | F64: =IFERROR(COUNT(F7:F58),"") -> 0 | G64: =IFERROR(COUNT(G7:G58),"") -> 0 | H64: =IFERROR(COUNT(H7:H58),"") -> 0 | I64: =IFERROR(COUNT(I7:I58),"") -> 0 | J64: =IFERROR(COUNT(J7:J58),"") -> 0 | ... M64: =IFERROR(COUNT(M7:M58),"") -> 0
B65: Totals, ranks and statistics include only fully graded quizzes (Status = Graded).

Sheet Performance per Problem
A1: Performance per Problem
A2: All statistics are formulas that read the Quiz 2 Grades sheet (students with no scores are excluded). Use the Flag column to decide what to review in class.
A4: Question | B4: Max Pts | C4: # Graded | D4: Average | E4: Average % | F4: Median | G4: Std Dev | H4: Lowest | I4: Highest | J4: # Full Marks | K4: % Full Marks | L4: # Zeros | M4: % Zeros | N4: Flag | P4: Flag thresholds
A5: ='Quiz 2 Grades'!C6 -> 1.1 | B5: ='Quiz 2 Grades'!C$5 -> 15 | C5: =COUNT('Quiz 2 Grades'!C$7:C$58) -> 0 | D5: =IFERROR(AVERAGE('Quiz 2 Grades'!C$7:C$58),"") | E5: =IFERROR(D5/B5,"") | F5: =IFERROR(MEDIAN('Quiz 2 Grades'!C$7:C$58),"") | G5: =IFERROR(STDEV('Quiz 2 Grades'!C$7:C$58),"") | H5: =IFERROR(MIN('Quiz 2 Grades'!C$7:C$58),"") -> 0 | I5: =IFERROR(MAX('Quiz 2 Grades'!C$7:C$58),"") -> 0 | J5: =COUNTIF('Quiz 2 Grades'!C$7:C$58,B5) -> 0 | K5: =IFERROR(J5/C5,"") | L5: =COUNTIF('Quiz 2 Grades'!C$7:C$58,0) -> 0 | M5: =IFERROR(L5/C5,"") | N5: =IF(ISNUMBER(E5),IF(OR(E5<$Q$6,AND(ISNUMBER(M5),M5>=$Q$7)),"Review in class",IF(E5<$Q$5,"Monitor","OK")),"") | P5: OK if average % ≥ | Q5: 0.75
A6: ='Quiz 2 Grades'!D6 -> 1.2 a | B6: ='Quiz 2 Grades'!D$5 -> 6 | C6: =COUNT('Quiz 2 Grades'!D$7:D$58) -> 0 | D6: =IFERROR(AVERAGE('Quiz 2 Grades'!D$7:D$58),"") | E6: =IFERROR(D6/B6,"") | F6: =IFERROR(MEDIAN('Quiz 2 Grades'!D$7:D$58),"") | G6: =IFERROR(STDEV('Quiz 2 Grades'!D$7:D$58),"") | H6: =IFERROR(MIN('Quiz 2 Grades'!D$7:D$58),"") -> 0 | I6: =IFERROR(MAX('Quiz 2 Grades'!D$7:D$58),"") -> 0 | J6: =COUNTIF('Quiz 2 Grades'!D$7:D$58,B6) -> 0 | K6: =IFERROR(J6/C6,"") | L6: =COUNTIF('Quiz 2 Grades'!D$7:D$58,0) -> 0 | M6: =IFERROR(L6/C6,"") | N6: =IF(ISNUMBER(E6),IF(OR(E6<$Q$6,AND(ISNUMBER(M6),M6>=$Q$7)),"Review in class",IF(E6<$Q$5,"Monitor","OK")),"") | P6: Review in class if average % < | Q6: 0.6
A7: ='Quiz 2 Grades'!E6 -> 1.2 b | B7: ='Quiz 2 Grades'!E$5 -> 1 | C7: =COUNT('Quiz 2 Grades'!E$7:E$58) -> 0 | D7: =IFERROR(AVERAGE('Quiz 2 Grades'!E$7:E$58),"") | E7: =IFERROR(D7/B7,"") | F7: =IFERROR(MEDIAN('Quiz 2 Grades'!E$7:E$58),"") | G7: =IFERROR(STDEV('Quiz 2 Grades'!E$7:E$58),"") | H7: =IFERROR(MIN('Quiz 2 Grades'!E$7:E$58),"") -> 0 | I7: =IFERROR(MAX('Quiz 2 Grades'!E$7:E$58),"") -> 0 | J7: =COUNTIF('Quiz 2 Grades'!E$7:E$58,B7) -> 0 | K7: =IFERROR(J7/C7,"") | L7: =COUNTIF('Quiz 2 Grades'!E$7:E$58,0) -> 0 | M7: =IFERROR(L7/C7,"") | N7: =IF(ISNUMBER(E7),IF(OR(E7<$Q$6,AND(ISNUMBER(M7),M7>=$Q$7)),"Review in class",IF(E7<$Q$5,"Monitor","OK")),"") | P7: …or if % of zeros ≥ | Q7: 0.25
A8: ='Quiz 2 Grades'!F6 -> 1.2 c | B8: ='Quiz 2 Grades'!F$5 -> 3 | C8: =COUNT('Quiz 2 Grades'!F$7:F$58) -> 0 | D8: =IFERROR(AVERAGE('Quiz 2 Grades'!F$7:F$58),"") | E8: =IFERROR(D8/B8,"") | F8: =IFERROR(MEDIAN('Quiz 2 Grades'!F$7:F$58),"") | G8: =IFERROR(STDEV('Quiz 2 Grades'!F$7:F$58),"") | H8: =IFERROR(MIN('Quiz 2 Grades'!F$7:F$58),"") -> 0 | I8: =IFERROR(MAX('Quiz 2 Grades'!F$7:F$58),"") -> 0 | J8: =COUNTIF('Quiz 2 Grades'!F$7:F$58,B8) -> 0 | K8: =IFERROR(J8/C8,"") | L8: =COUNTIF('Quiz 2 Grades'!F$7:F$58,0) -> 0 | M8: =IFERROR(L8/C8,"") | N8: =IF(ISNUMBER(E8),IF(OR(E8<$Q$6,AND(ISNUMBER(M8),M8>=$Q$7)),"Review in class",IF(E8<$Q$5,"Monitor","OK")),"") | P8: (otherwise, below the OK line = Monitor)
A9: ='Quiz 2 Grades'!G6 -> 1.3 | B9: ='Quiz 2 Grades'!G$5 -> 10 | C9: =COUNT('Quiz 2 Grades'!G$7:G$58) -> 0 | D9: =IFERROR(AVERAGE('Quiz 2 Grades'!G$7:G$58),"") | E9: =IFERROR(D9/B9,"") | F9: =IFERROR(MEDIAN('Quiz 2 Grades'!G$7:G$58),"") | G9: =IFERROR(STDEV('Quiz 2 Grades'!G$7:G$58),"") | H9: =IFERROR(MIN('Quiz 2 Grades'!G$7:G$58),"") -> 0 | I9: =IFERROR(MAX('Quiz 2 Grades'!G$7:G$58),"") -> 0 | J9: =COUNTIF('Quiz 2 Grades'!G$7:G$58,B9) -> 0 | K9: =IFERROR(J9/C9,"") | L9: =COUNTIF('Quiz 2 Grades'!G$7:G$58,0) -> 0 | M9: =IFERROR(L9/C9,"") | N9: =IF(ISNUMBER(E9),IF(OR(E9<$Q$6,AND(ISNUMBER(M9),M9>=$Q$7)),"Review in class",IF(E9<$Q$5,"Monitor","OK")),"")
A10: ='Quiz 2 Grades'!I6 -> 2.1 | B10: ='Quiz 2 Grades'!I$5 -> 5 | C10: =COUNT('Quiz 2 Grades'!I$7:I$58) -> 0 | D10: =IFERROR(AVERAGE('Quiz 2 Grades'!I$7:I$58),"") | E10: =IFERROR(D10/B10,"") | F10: =IFERROR(MEDIAN('Quiz 2 Grades'!I$7:I$58),"") | G10: =IFERROR(STDEV('Quiz 2 Grades'!I$7:I$58),"") | H10: =IFERROR(MIN('Quiz 2 Grades'!I$7:I$58),"") -> 0 | I10: =IFERROR(MAX('Quiz 2 Grades'!I$7:I$58),"") -> 0 | J10: =COUNTIF('Quiz 2 Grades'!I$7:I$58,B10) -> 0 | K10: =IFERROR(J10/C10,"") | L10: =COUNTIF('Quiz 2 Grades'!I$7:I$58,0) -> 0 | M10: =IFERROR(L10/C10,"") | N10: =IF(ISNUMBER(E10),IF(OR(E10<$Q$6,AND(ISNUMBER(M10),M10>=$Q$7)),"Review in class",IF(E10<$Q$5,"Monitor","OK")),"")
A11: ='Quiz 2 Grades'!J6 -> 2.2 | B11: ='Quiz 2 Grades'!J$5 -> 5 | C11: =COUNT('Quiz 2 Grades'!J$7:J$58) -> 0 | D11: =IFERROR(AVERAGE('Quiz 2 Grades'!J$7:J$58),"") | E11: =IFERROR(D11/B11,"") | F11: =IFERROR(MEDIAN('Quiz 2 Grades'!J$7:J$58),"") | G11: =IFERROR(STDEV('Quiz 2 Grades'!J$7:J$58),"") | H11: =IFERROR(MIN('Quiz 2 Grades'!J$7:J$58),"") -> 0 | I11: =IFERROR(MAX('Quiz 2 Grades'!J$7:J$58),"") -> 0 | J11: =COUNTIF('Quiz 2 Grades'!J$7:J$58,B11) -> 0 | K11: =IFERROR(J11/C11,"") | L11: =COUNTIF('Quiz 2 Grades'!J$7:J$58,0) -> 0 | M11: =IFERROR(L11/C11,"") | N11: =IF(ISNUMBER(E11),IF(OR(E11<$Q$6,AND(ISNUMBER(M11),M11>=$Q$7)),"Review in class",IF(E11<$Q$5,"Monitor","OK")),"")
A12: ='Quiz 2 Grades'!K6 -> 2.3 | B12: ='Quiz 2 Grades'!K$5 -> 5 | C12: =COUNT('Quiz 2 Grades'!K$7:K$58) -> 0 | D12: =IFERROR(AVERAGE('Quiz 2 Grades'!K$7:K$58),"") | E12: =IFERROR(D12/B12,"") | F12: =IFERROR(MEDIAN('Quiz 2 Grades'!K$7:K$58),"") | G12: =IFERROR(STDEV('Quiz 2 Grades'!K$7:K$58),"") | H12: =IFERROR(MIN('Quiz 2 Grades'!K$7:K$58),"") -> 0 | I12: =IFERROR(MAX('Quiz 2 Grades'!K$7:K$58),"") -> 0 | J12: =COUNTIF('Quiz 2 Grades'!K$7:K$58,B12) -> 0 | K12: =IFERROR(J12/C12,"") | L12: =COUNTIF('Quiz 2 Grades'!K$7:K$58,0) -> 0 | M12: =IFERROR(L12/C12,"") | N12: =IF(ISNUMBER(E12),IF(OR(E12<$Q$6,AND(ISNUMBER(M12),M12>=$Q$7)),"Review in class",IF(E12<$Q$5,"Monitor","OK")),"")
A13: Problem 1 total | B13: ='Quiz 2 Grades'!H$5 -> 35 | C13: =COUNT('Quiz 2 Grades'!H$7:H$58) -> 0 | D13: =IFERROR(AVERAGE('Quiz 2 Grades'!H$7:H$58),"") | E13: =IFERROR(D13/B13,"") | F13: =IFERROR(MEDIAN('Quiz 2 Grades'!H$7:H$58),"") | G13: =IFERROR(STDEV('Quiz 2 Grades'!H$7:H$58),"") | H13: =IFERROR(MIN('Quiz 2 Grades'!H$7:H$58),"") -> 0 | I13: =IFERROR(MAX('Quiz 2 Grades'!H$7:H$58),"") -> 0 | J13: =COUNTIF('Quiz 2 Grades'!H$7:H$58,B13) -> 0 | K13: =IFERROR(J13/C13,"") | L13: =COUNTIF('Quiz 2 Grades'!H$7:H$58,0) -> 0 | M13: =IFERROR(L13/C13,"") | N13: =IF(ISNUMBER(E13),IF(OR(E13<$Q$6,AND(ISNUMBER(M13),M13>=$Q$7)),"Review in class",IF(E13<$Q$5,"Monitor","OK")),"")
A14: Problem 2 total | B14: ='Quiz 2 Grades'!L$5 -> 15 | C14: =COUNT('Quiz 2 Grades'!L$7:L$58) -> 0 | D14: =IFERROR(AVERAGE('Quiz 2 Grades'!L$7:L$58),"") | E14: =IFERROR(D14/B14,"") | F14: =IFERROR(MEDIAN('Quiz 2 Grades'!L$7:L$58),"") | G14: =IFERROR(STDEV('Quiz 2 Grades'!L$7:L$58),"") | H14: =IFERROR(MIN('Quiz 2 Grades'!L$7:L$58),"") -> 0 | I14: =IFERROR(MAX('Quiz 2 Grades'!L$7:L$58),"") -> 0 | J14: =COUNTIF('Quiz 2 Grades'!L$7:L$58,B14) -> 0 | K14: =IFERROR(J14/C14,"") | L14: =COUNTIF('Quiz 2 Grades'!L$7:L$58,0) -> 0 | M14: =IFERROR(L14/C14,"") | N14: =IF(ISNUMBER(E14),IF(OR(E14<$Q$6,AND(ISNUMBER(M14),M14>=$Q$7)),"Review in class",IF(E14<$Q$5,"Monitor","OK")),"")
A15: QUIZ TOTAL | B15: ='Quiz 2 Grades'!M$5 -> 50 | C15: =COUNT('Quiz 2 Grades'!M$7:M$58) -> 0 | D15: =IFERROR(AVERAGE('Quiz 2 Grades'!M$7:M$58),"") | E15: =IFERROR(D15/B15,"") | F15: =IFERROR(MEDIAN('Quiz 2 Grades'!M$7:M$58),"") | G15: =IFERROR(STDEV('Quiz 2 Grades'!M$7:M$58),"") | H15: =IFERROR(MIN('Quiz 2 Grades'!M$7:M$58),"") -> 0 | I15: =IFERROR(MAX('Quiz 2 Grades'!M$7:M$58),"") -> 0 | J15: =COUNTIF('Quiz 2 Grades'!M$7:M$58,B15) -> 0 | K15: =IFERROR(J15/C15,"") | L15: =COUNTIF('Quiz 2 Grades'!M$7:M$58,0) -> 0 | M15: =IFERROR(L15/C15,"") | N15: =IF(ISNUMBER(E15),IF(OR(E15<$Q$6,AND(ISNUMBER(M15),M15>=$Q$7)),"Review in class",IF(E15<$Q$5,"Monitor","OK")),"")

Sheet Class Summary
A1: Quiz 2 — Class Summary
A2: Everything on this sheet is calculated from the Quiz 2 Grades and Roster sheets (fully graded quizzes only).
A4: At a glance | E4: Performance bands
A5: Students on roster | B5: =COUNTA(Roster!$B$5:$B$56) -> 52 | E5: Band | F5: Range | G5: # Students | H5: % of graded
A6: Quizzes fully graded | B6: =COUNTIF('Quiz 2 Grades'!$Q$7:$Q$58,"Graded") -> 0 | E6: Strong | F6: ="≥ "&'Quiz 2 Grades'!$T$3 -> ≥ 40 | G6: =COUNTIF('Quiz 2 Grades'!$O$7:$O$58,E6) -> 0 | H6: =IFERROR(G6/SUM($G$6:$G$8),"")
A7: Incomplete (some scores missing) | B7: =COUNTIF('Quiz 2 Grades'!$Q$7:$Q$58,"Incomplete") -> 0 | E7: Satisfactory | F7: ='Quiz 2 Grades'!$T$4&" – "&('Quiz 2 Grades'!$T$3-1) -> 26 – 39 | G7: =COUNTIF('Quiz 2 Grades'!$O$7:$O$58,E7) -> 0 | H7: =IFERROR(G7/SUM($G$6:$G$8),"")
A8: Missing (no scores) | B8: =COUNTIF('Quiz 2 Grades'!$Q$7:$Q$58,"Missing") -> 52 | E8: Needs support | F8: ="< "&'Quiz 2 Grades'!$T$4 -> < 26 | G8: =COUNTIF('Quiz 2 Grades'!$O$7:$O$58,E8) -> 0 | H8: =IFERROR(G8/SUM($G$6:$G$8),"")
A9: Class average (/50) | B9: =IFERROR(AVERAGE('Quiz 2 Grades'!$M$7:$M$58),"") | E9: Total graded | G9: =SUM(G6:G8) -> 0
A10: Class average (%) | B10: =IFERROR(B9/'Quiz 2 Grades'!$M$5,"")
A11: Median (/50) | B11: =IFERROR(MEDIAN('Quiz 2 Grades'!$M$7:$M$58),"")
A12: Standard deviation | B12: =IFERROR(STDEV('Quiz 2 Grades'!$M$7:$M$58),"")
A13: Highest score | B13: =IFERROR(MAX('Quiz 2 Grades'!$M$7:$M$58),"") -> 0
A14: Lowest score | B14: =IFERROR(MIN('Quiz 2 Grades'!$M$7:$M$58),"") -> 0
A16: Score distribution (total /50)
A17: Score range | B17: From | C17: To | D17: # Students
A18: =B18&"–"&C18 -> 0–9 | B18: 0 | C18: 9 | D18: =COUNTIFS('Quiz 2 Grades'!$M$7:$M$58,">="&B18,'Quiz 2 Grades'!$M$7:$M$58,"<"&(C18+1)) -> 0
A19: =B19&"–"&C19 -> 10–19 | B19: 10 | C19: 19 | D19: =COUNTIFS('Quiz 2 Grades'!$M$7:$M$58,">="&B19,'Quiz 2 Grades'!$M$7:$M$58,"<"&(C19+1)) -> 0
A20: =B20&"–"&C20 -> 20–29 | B20: 20 | C20: 29 | D20: =COUNTIFS('Quiz 2 Grades'!$M$7:$M$58,">="&B20,'Quiz 2 Grades'!$M$7:$M$58,"<"&(C20+1)) -> 0
A21: =B21&"–"&C21 -> 30–39 | B21: 30 | C21: 39 | D21: =COUNTIFS('Quiz 2 Grades'!$M$7:$M$58,">="&B21,'Quiz 2 Grades'!$M$7:$M$58,"<"&(C21+1)) -> 0
A22: =B22&"–"&C22 -> 40–50 | B22: 40 | C22: 50 | D22: =COUNTIFS('Quiz 2 Grades'!$M$7:$M$58,">="&B22,'Quiz 2 Grades'!$M$7:$M$58,"<"&(C22+1)) -> 0
A23: Total | D23: =SUM(D18:D22) -> 0
A24: Check: equals quizzes fully graded? | D24: =IF(D23=B6,"✔ OK","Check bins") -> ✔ OK

Sheet Statistical Analysis
A1: Statistical Analysis — Quiz 2 (Gaussian fit)
A2: Every value is a formula over the fully graded Quiz 2 totals, so the analysis updates when grades change. Blue cells = settings you can change. Tests use α = 0.05 (cell B34).
A4: Key findings (these sentences update automatically)
A5: =IF(nGraded<2,"Center: shown once at least 2 quizzes are fully graded (now "&nGraded&").","Center: mean "&TEXT(MeanScore,"0.0")&" / "&MaxScore&" ("&TEXT(MeanScore/MaxScore,"0%")&"), median "&TEXT(MedianScore,"0.0")&" ("&TEXT(MedianScore/MaxScore,"0%")&"). "&TEXT($B$35,"0%")&" confidence interval for the class mean: "&TEXT($B$21,"0.0")&" – "&TEXT($B$22,"0.0")&" points (n = "&nGraded&").") -> Center: shown once at least 2 quizzes are fully graded (now 0).
A6: =IF(nGraded<2,"Spread: shown once at least 2 quizzes are fully graded (now "&nGraded&").","Spread: standard deviation "&TEXT(SDScore,"0.0")&" points (CV "&TEXT($B$29,"0%")&"). The middle 50% of students scored between "&TEXT($B$24,"0")&" and "&TEXT($B$25,"0")&"; range "&$B$23&" – "&$B$26&".") -> Spread: shown once at least 2 quizzes are fully graded (now 0).
A7: =IF(nGraded<4,"Shape: shown once at least 4 quizzes are fully graded (now "&nGraded&").",IF(SkewScore<=-0.5,"Shape: left-skewed (skewness "&TEXT(SkewScore,"0.00")&") — most students scored high, with a tail of low scores, so the median ("&TEXT(MedianScore,"0.0")&") describes the typical student better than the mean.",IF(SkewScore>=0.5,"Shape: right-skewed (skewness "&TEXT(SkewScore,"0.00")&") — most students scored low with a few high scores.","Shape: roughly symmetric (skewness "&TEXT(SkewScore,"0.00")&")."))&IF(KurtScore<=-0.5," The peak is flatter than a bell curve (excess kurtosis "&TEXT(KurtScore,"0.00")&"): scores are spread out rather than piled up near the mean.",IF(KurtScore>=0.5," The peak is sharper than a bell curve (excess kurtosis "&TEXT(KurtScore,"0.00")&").",""))) -> Shape: shown once at least 4 quizzes are fully graded (now 0).
A8: =IF(nGraded<12,"Normality: need at least 12 graded quizzes.",IF(AND($L$19>=Alpha,$L$18>=Alpha),"Normality: consistent with a Gaussian distribution (Shapiro–Wilk p = "&TEXT($L$19,"0.000")&", Anderson–Darling p = "&TEXT($L$18,"0.000")&"), so z-scores and σ-bands are a fair summary of standing.",IF(AND($L$19<Alpha,$L$18<Alpha),"Normality: the scores are NOT Gaussian (Shapiro–Wilk p = "&TEXT($L$19,"0.000")&", Anderson–Darling p = "&TEXT($L$18,"0.000")&") — see the shape and ceiling notes. Use the median and percentiles as the main summary and treat z-scores as approximate; avoid curving grades with a normal curve.","Normality: borderline — Shapiro–Wilk p = "&TEXT($L$19,"0.000")&", Anderson–Darling p = "&TEXT($L$18,"0.000")&". The Gaussian curve is a rough approximation only."))) -> Normality: need at least 12 graded quizzes.
A9: =IF(nGraded<2,"Ceiling: shown once at least 2 quizzes are fully graded (now "&nGraded&").","Ceiling: a Gaussian curve with this mean and SD would place "&TEXT(G51,"0.0%")&" of students above the maximum of "&MaxScore&" points, and "&COUNTIF(Totals,MaxScore)&" students scored exactly "&MaxScore&"."&IF(G51>=0.05," This ceiling effect means the quiz could not separate the strongest students (and is one reason the distribution is not bell-shaped).","")) -> Ceiling: shown once at least 2 quizzes are fully graded (now 0).
A10: =IF(nGraded<2,"Lower tail: shown once at least 2 quizzes are fully graded (now "&nGraded&").","Lower tail: "&COUNTIF(Totals,"<"&(MeanScore-SDScore))&" students scored more than 1σ below the mean (below "&TEXT(MeanScore-SDScore,"0.0")&") and "&COUNTIF(Totals,"<"&(MeanScore-2*SDScore))&" more than 2σ below (below "&TEXT(MeanScore-2*SDScore,"0.0")&"); a Gaussian curve predicts "&TEXT(nGraded*(1-NORMSDIST(1)),"0")&" and "&TEXT(nGraded*(1-NORMSDIST(2)),"0")&". See section 6 for names.") -> Lower tail: shown once at least 2 quizzes are fully graded (now 0).
A11: =IFERROR("Questions: reliability (Cronbach's α) = "&TEXT(C65,"0.00")&" ("&LOWER(D65)&"). Hardest question: "&INDEX(A57:A64,MATCH(MIN(D57:D64),D57:D64,0))&" (average "&TEXT(MIN(D57:D64),"0%")&"). Weakest at separating strong from weak students: "&INDEX(A57:A64,MATCH(MIN(F57:F64),F57:F64,0))&" (item–rest r = "&TEXT(MIN(F57:F64),"0.00")&").","Questions: not enough graded quizzes for item analysis.") -> Questions: not enough graded quizzes for item analysis.
A13: 1. Descriptive statistics | J13: 2. Is the class distribution Gaussian? (normality tests) | P13: Calculation helpers (formulas — do not edit) | Y13: Test intermediates | AB13: Graded-only data for item analysis (formulas — do not edit)
A14: Statistic | B14: Value | C14: Note | J14: Test | K14: Statistic | L14: p-value | M14: Verdict | N14: What it checks | P14: i | Q14: Sorted score y(i) | R14: Plot position p | S14: Normal quantile m | T14: Expected score (Q–Q x) | U14: SW weight a | V14: a × y(i) | W14: AD term | AB14: Total | AC14: 1.1 | AD14: 1.2 a | AE14: 1.2 b | AF14: 1.2 c | AG14: 1.3 | AH14: 2.1 | AI14: 2.2 | AJ14: 2.3 | AK14: Rest 1.1 | AL14: Rest 1.2 a | AM14: Rest 1.2 b | AN14: Rest 1.2 c | AO14: Rest 1.3 | AP14: Rest 2.1 | AQ14: Rest 2.2 | AR14: Rest 2.3
A15: Graded quizzes (n) | B15: =COUNT(Totals) -> 0 | C15: Only fully graded quizzes count | J15: Skewness z-test | K15: =IFERROR(SkewScore/$Z$33,"") | L15: =IFERROR(2*(1-NORMSDIST(ABS(K15))),"") | M15: =IF(ISNUMBER(L15),IF(L15<Alpha,"Not normal (p < α)","Consistent with normal"),"") | N15: Symmetry (z = skewness ÷ its standard error) | P15: 1 | Q15: =IF(P15<=nGraded,SMALL(Totals,P15),NA()) -> #N/A | R15: =IF(P15<=nGraded,(P15-0.375)/(nGraded+0.25),"") | S15: =IF(P15<=nGraded,NORMSINV(R15),"") | T15: =IFERROR(IF(P15<=nGraded,MeanScore+SDScore*S15,NA()),NA()) -> #N/A | U15: =IFERROR(IF(P15>nGraded,"",IF(P15=nGraded,$Z$19,IF(P15=nGraded-1,$Z$20,IF(P15=1,-$Z$19,IF(P15=2,-$Z$20,S15/SQRT($Z$21)))))),"") | V15: =IFERROR(IF(P15<=nGraded,U15*Q15,""),"") | W15: =IFERROR(IF(P15<=nGraded,(2*P15-1)*(LN(NORMDIST(Q15,MeanScore,SDScore,TRUE()))+LN(1-NORMDIST(LARGE(Totals,P15),MeanScore,SDScore,TRUE()))),""),"") | Y15: Σ m² | Z15: =IFERROR(SUMSQ(S15:S66),"") -> 0 | AB15: =IF('Quiz 2 Grades'!$Q7="Graded",'Quiz 2 Grades'!$M7,"") | AC15: =IF('Quiz 2 Grades'!$Q7="Graded",'Quiz 2 Grades'!C7,"") | AD15: =IF('Quiz 2 Grades'!$Q7="Graded",'Quiz 2 Grades'!D7,"") | AE15: =IF('Quiz 2 Grades'!$Q7="Graded",'Quiz 2 Grades'!E7,"") | AF15: =IF('Quiz 2 Grades'!$Q7="Graded",'Quiz 2 Grades'!F7,"") | AG15: =IF('Quiz 2 Grades'!$Q7="Graded",'Quiz 2 Grades'!G7,"") | AH15: =IF('Quiz 2 Grades'!$Q7="Graded",'Quiz 2 Grades'!I7,"") | AI15: =IF('Quiz 2 Grades'!$Q7="Graded",'Quiz 2 Grades'!J7,"") | AJ15: =IF('Quiz 2 Grades'!$Q7="Graded",'Quiz 2 Grades'!K7,"") | AK15: =IF(ISNUMBER(AB15),AB15-AC15,"") | AL15: =IF(ISNUMBER(AB15),AB15-AD15,"") | AM15: =IF(ISNUMBER(AB15),AB15-AE15,"") | AN15: =IF(ISNUMBER(AB15),AB15-AF15,"") | AO15: =IF(ISNUMBER(AB15),AB15-AG15,"") | AP15: =IF(ISNUMBER(AB15),AB15-AH15,"") | AQ15: =IF(ISNUMBER(AB15),AB15-AI15,"") | AR15: =IF(ISNUMBER(AB15),AB15-AJ15,"")
A16: Mean (points) | B16: =IFERROR(AVERAGE(Totals),"") | J16: Kurtosis z-test | K16: =IFERROR(KurtScore/$Z$34,"") | L16: =IFERROR(2*(1-NORMSDIST(ABS(K16))),"") | M16: =IF(ISNUMBER(L16),IF(L16<Alpha,"Not normal (p < α)","Consistent with normal"),"") | N16: Peak / tails vs. a bell curve | P16: 2 | Q16: =IF(P16<=nGraded,SMALL(Totals,P16),NA()) -> #N/A | R16: =IF(P16<=nGraded,(P16-0.375)/(nGraded+0.25),"") | S16: =IF(P16<=nGraded,NORMSINV(R16),"") | T16: =IFERROR(IF(P16<=nGraded,MeanScore+SDScore*S16,NA()),NA()) -> #N/A | U16: =IFERROR(IF(P16>nGraded,"",IF(P16=nGraded,$Z$19,IF(P16=nGraded-1,$Z$20,IF(P16=1,-$Z$19,IF(P16=2,-$Z$20,S16/SQRT($Z$21)))))),"") | V16: =IFERROR(IF(P16<=nGraded,U16*Q16,""),"") | W16: =IFERROR(IF(P16<=nGraded,(2*P16-1)*(LN(NORMDIST(Q16,MeanScore,SDScore,TRUE()))+LN(1-NORMDIST(LARGE(Totals,P16),MeanScore,SDScore,TRUE()))),""),"") | Y16: u = 1/√n | Z16: =IFERROR(1/SQRT(nGraded),"") | AB16: =IF('Quiz 2 Grades'!$Q8="Graded",'Quiz 2 Grades'!$M8,"") | AC16: =IF('Quiz 2 Grades'!$Q8="Graded",'Quiz 2 Grades'!C8,"") | AD16: =IF('Quiz 2 Grades'!$Q8="Graded",'Quiz 2 Grades'!D8,"") | AE16: =IF('Quiz 2 Grades'!$Q8="Graded",'Quiz 2 Grades'!E8,"") | AF16: =IF('Quiz 2 Grades'!$Q8="Graded",'Quiz 2 Grades'!F8,"") | AG16: =IF('Quiz 2 Grades'!$Q8="Graded",'Quiz 2 Grades'!G8,"") | AH16: =IF('Quiz 2 Grades'!$Q8="Graded",'Quiz 2 Grades'!I8,"") | AI16: =IF('Quiz 2 Grades'!$Q8="Graded",'Quiz 2 Grades'!J8,"") | AJ16: =IF('Quiz 2 Grades'!$Q8="Graded",'Quiz 2 Grades'!K8,"") | AK16: =IF(ISNUMBER(AB16),AB16-AC16,"") | AL16: =IF(ISNUMBER(AB16),AB16-AD16,"") | AM16: =IF(ISNUMBER(AB16),AB16-AE16,"") | AN16: =IF(ISNUMBER(AB16),AB16-AF16,"") | AO16: =IF(ISNUMBER(AB16),AB16-AG16,"") | AP16: =IF(ISNUMBER(AB16),AB16-AH16,"") | AQ16: =IF(ISNUMBER(AB16),AB16-AI16,"") | AR16: =IF(ISNUMBER(AB16),AB16-AJ16,"")
A17: Median (points) | B17: =IFERROR(MEDIAN(Totals),"") | C17: Middle student | J17: Jarque–Bera | K17: =IFERROR(nGraded/6*(SkewScore^2+KurtScore^2/4),"") | L17: =IFERROR(CHIDIST(K17,2),"") | M17: =IF(ISNUMBER(L17),IF(L17<Alpha,"Not normal (p < α)","Consistent with normal"),"") | N17: Skewness + kurtosis together (large-sample test) | P17: 3 | Q17: =IF(P17<=nGraded,SMALL(Totals,P17),NA()) -> #N/A | R17: =IF(P17<=nGraded,(P17-0.375)/(nGraded+0.25),"") | S17: =IF(P17<=nGraded,NORMSINV(R17),"") | T17: =IFERROR(IF(P17<=nGraded,MeanScore+SDScore*S17,NA()),NA()) -> #N/A | U17: =IFERROR(IF(P17>nGraded,"",IF(P17=nGraded,$Z$19,IF(P17=nGraded-1,$Z$20,IF(P17=1,-$Z$19,IF(P17=2,-$Z$20,S17/SQRT($Z$21)))))),"") | V17: =IFERROR(IF(P17<=nGraded,U17*Q17,""),"") | W17: =IFERROR(IF(P17<=nGraded,(2*P17-1)*(LN(NORMDIST(Q17,MeanScore,SDScore,TRUE()))+LN(1-NORMDIST(LARGE(Totals,P17),MeanScore,SDScore,TRUE()))),""),"") | Y17: c(n) = m(n)/√Σm² | Z17: =IFERROR(INDEX(S15:S66,nGraded)/SQRT(Z15),"") | AB17: =IF('Quiz 2 Grades'!$Q9="Graded",'Quiz 2 Grades'!$M9,"") | AC17: =IF('Quiz 2 Grades'!$Q9="Graded",'Quiz 2 Grades'!C9,"") | AD17: =IF('Quiz 2 Grades'!$Q9="Graded",'Quiz 2 Grades'!D9,"") | AE17: =IF('Quiz 2 Grades'!$Q9="Graded",'Quiz 2 Grades'!E9,"") | AF17: =IF('Quiz 2 Grades'!$Q9="Graded",'Quiz 2 Grades'!F9,"") | AG17: =IF('Quiz 2 Grades'!$Q9="Graded",'Quiz 2 Grades'!G9,"") | AH17: =IF('Quiz 2 Grades'!$Q9="Graded",'Quiz 2 Grades'!I9,"") | AI17: =IF('Quiz 2 Grades'!$Q9="Graded",'Quiz 2 Grades'!J9,"") | AJ17: =IF('Quiz 2 Grades'!$Q9="Graded",'Quiz 2 Grades'!K9,"") | AK17: =IF(ISNUMBER(AB17),AB17-AC17,"") | AL17: =IF(ISNUMBER(AB17),AB17-AD17,"") | AM17: =IF(ISNUMBER(AB17),AB17-AE17,"") | AN17: =IF(ISNUMBER(AB17),AB17-AF17,"") | AO17: =IF(ISNUMBER(AB17),AB17-AG17,"") | AP17: =IF(ISNUMBER(AB17),AB17-AH17,"") | AQ17: =IF(ISNUMBER(AB17),AB17-AI17,"") | AR17: =IF(ISNUMBER(AB17),AB17-AJ17,"")
A18: Standard deviation (sample) | B18: =IFERROR(STDEV(Totals),"") | C18: Typical distance from the mean | J18: Anderson–Darling (A²*) | K18: =IFERROR($Z$31,"") | L18: =IFERROR(MIN(1,MAX(0,$Z$32)),"") -> 0 | M18: =IF(ISNUMBER(L18),IF(L18<Alpha,"Not normal (p < α)","Consistent with normal"),"") -> Not normal (p < α) | N18: Whole distribution, extra weight on the tails | P18: 4 | Q18: =IF(P18<=nGraded,SMALL(Totals,P18),NA()) -> #N/A | R18: =IF(P18<=nGraded,(P18-0.375)/(nGraded+0.25),"") | S18: =IF(P18<=nGraded,NORMSINV(R18),"") | T18: =IFERROR(IF(P18<=nGraded,MeanScore+SDScore*S18,NA()),NA()) -> #N/A | U18: =IFERROR(IF(P18>nGraded,"",IF(P18=nGraded,$Z$19,IF(P18=nGraded-1,$Z$20,IF(P18=1,-$Z$19,IF(P18=2,-$Z$20,S18/SQRT($Z$21)))))),"") | V18: =IFERROR(IF(P18<=nGraded,U18*Q18,""),"") | W18: =IFERROR(IF(P18<=nGraded,(2*P18-1)*(LN(NORMDIST(Q18,MeanScore,SDScore,TRUE()))+LN(1-NORMDIST(LARGE(Totals,P18),MeanScore,SDScore,TRUE()))),""),"") | Y18: c(n−1) | Z18: =IFERROR(INDEX(S15:S66,nGraded-1)/SQRT(Z15),"") | AB18: =IF('Quiz 2 Grades'!$Q10="Graded",'Quiz 2 Grades'!$M10,"") | AC18: =IF('Quiz 2 Grades'!$Q10="Graded",'Quiz 2 Grades'!C10,"") | AD18: =IF('Quiz 2 Grades'!$Q10="Graded",'Quiz 2 Grades'!D10,"") | AE18: =IF('Quiz 2 Grades'!$Q10="Graded",'Quiz 2 Grades'!E10,"") | AF18: =IF('Quiz 2 Grades'!$Q10="Graded",'Quiz 2 Grades'!F10,"") | AG18: =IF('Quiz 2 Grades'!$Q10="Graded",'Quiz 2 Grades'!G10,"") | AH18: =IF('Quiz 2 Grades'!$Q10="Graded",'Quiz 2 Grades'!I10,"") | AI18: =IF('Quiz 2 Grades'!$Q10="Graded",'Quiz 2 Grades'!J10,"") | AJ18: =IF('Quiz 2 Grades'!$Q10="Graded",'Quiz 2 Grades'!K10,"") | AK18: =IF(ISNUMBER(AB18),AB18-AC18,"") | AL18: =IF(ISNUMBER(AB18),AB18-AD18,"") | AM18: =IF(ISNUMBER(AB18),AB18-AE18,"") | AN18: =IF(ISNUMBER(AB18),AB18-AF18,"") | AO18: =IF(ISNUMBER(AB18),AB18-AG18,"") | AP18: =IF(ISNUMBER(AB18),AB18-AH18,"") | AQ18: =IF(ISNUMBER(AB18),AB18-AI18,"") | AR18: =IF(ISNUMBER(AB18),AB18-AJ18,"")
A19: Variance | B19: =IFERROR(VAR(Totals),"") | J19: Shapiro–Wilk (W) | K19: =IF(nGraded<12,"n < 12",IFERROR($Z$24,"")) -> n < 12 | L19: =IF(nGraded<12,"",IFERROR($Z$29,"")) | M19: =IF(ISNUMBER(L19),IF(L19<Alpha,"Not normal (p < α)","Consistent with normal"),"") | N19: Most powerful general test for n ≤ 50 (Royston 1992 approximation) | P19: 5 | Q19: =IF(P19<=nGraded,SMALL(Totals,P19),NA()) -> #N/A | R19: =IF(P19<=nGraded,(P19-0.375)/(nGraded+0.25),"") | S19: =IF(P19<=nGraded,NORMSINV(R19),"") | T19: =IFERROR(IF(P19<=nGraded,MeanScore+SDScore*S19,NA()),NA()) -> #N/A | U19: =IFERROR(IF(P19>nGraded,"",IF(P19=nGraded,$Z$19,IF(P19=nGraded-1,$Z$20,IF(P19=1,-$Z$19,IF(P19=2,-$Z$20,S19/SQRT($Z$21)))))),"") | V19: =IFERROR(IF(P19<=nGraded,U19*Q19,""),"") | W19: =IFERROR(IF(P19<=nGraded,(2*P19-1)*(LN(NORMDIST(Q19,MeanScore,SDScore,TRUE()))+LN(1-NORMDIST(LARGE(Totals,P19),MeanScore,SDScore,TRUE()))),""),"") | Y19: a(n) [Royston 1992] | Z19: =IFERROR(Z17+0.221157*Z16-0.147981*Z16^2-2.07119*Z16^3+4.434685*Z16^4-2.706056*Z16^5,"") | AB19: =IF('Quiz 2 Grades'!$Q11="Graded",'Quiz 2 Grades'!$M11,"") | AC19: =IF('Quiz 2 Grades'!$Q11="Graded",'Quiz 2 Grades'!C11,"") | AD19: =IF('Quiz 2 Grades'!$Q11="Graded",'Quiz 2 Grades'!D11,"") | AE19: =IF('Quiz 2 Grades'!$Q11="Graded",'Quiz 2 Grades'!E11,"") | AF19: =IF('Quiz 2 Grades'!$Q11="Graded",'Quiz 2 Grades'!F11,"") | AG19: =IF('Quiz 2 Grades'!$Q11="Graded",'Quiz 2 Grades'!G11,"") | AH19: =IF('Quiz 2 Grades'!$Q11="Graded",'Quiz 2 Grades'!I11,"") | AI19: =IF('Quiz 2 Grades'!$Q11="Graded",'Quiz 2 Grades'!J11,"") | AJ19: =IF('Quiz 2 Grades'!$Q11="Graded",'Quiz 2 Grades'!K11,"") | AK19: =IF(ISNUMBER(AB19),AB19-AC19,"") | AL19: =IF(ISNUMBER(AB19),AB19-AD19,"") | AM19: =IF(ISNUMBER(AB19),AB19-AE19,"") | AN19: =IF(ISNUMBER(AB19),AB19-AF19,"") | AO19: =IF(ISNUMBER(AB19),AB19-AG19,"") | AP19: =IF(ISNUMBER(AB19),AB19-AH19,"") | AQ19: =IF(ISNUMBER(AB19),AB19-AI19,"") | AR19: =IF(ISNUMBER(AB19),AB19-AJ19,"")
